Workbook

Sheet LEEME
A1: Ciclo Kalina KCS-11 — resultados de la campaña final de barridos (M1–M10b)
A3: Para qué es este libro: presentar las tablas y gráficos del análisis, ordenados por pregunta.
A4: Cómo se numera: pregunta (1–6) → estudio (2.4) → parte (2.4a). Ver la hoja Nomenclatura. Solo se comparan puntos de la misma parte.
A5: Cómo leer cada hoja: las primeras filas dicen qué caso es, el punto base, los datos fijos y barridos (parte por parte si hay varias), el filtro y la fuente; la tabla empieza después de una fila en blanco (con filtros); las notas van al final.
A6: Hoja Tablero: elija un estudio o una parte en la celda B2 y se actualizan las cifras, las condiciones y los gráficos.
A7: Hojas 'N Gráficos': gráficos nativos de Excel de cada pregunta (pase el cursor para ver los valores); cada uno lleva arriba su ID y título y abajo su pie con los datos fijos.
A8: Hojas 'N Datos de gráficos': los números con los que Excel dibuja cada gráfico, un bloque por figura (si cambia un número, el gráfico cambia).
A9: Cada gráfico, además, tiene una copia junto a la tabla de la que salen sus datos: a la derecha de su parte o variable en la hoja 'N.M-R Resultados por barrido', o debajo de su tabla resumen (3.1-3, 3.2-4, 4.3-3, 6.1-3, S-1). Los de 'N Gráficos' siguen donde estaban.
A10: Hojas 'N.M-R Resultados por barrido': por estudio, la tabla de cada barrido con el valor de la variable barrida, la clase, η, W_net, ΔP, r_P y si está fuera de rango (los mismos puntos del tablero HTML).
A12: Glosario:
A13: • PP (punto del profesor): Los datos del enunciado: P_alta 3000 kPa, P_baja 400 kPa, x_b 0.50, T_fuente 623.15 K, T_sumidero 300.03 K, η_t 0.85, η_p 0.75, ε_HRVG 0.85, ε_reg 0.75, ε_cond 0.80. Con ellos el ciclo no converge.
A14: • A* (punto ancla): El punto del profesor con solo dos cambios: T_fuente = 403 K y P_baja = 563.64 kPa. Es KALINA con η = 8.48 %. Se eligió en M2 como el cambio intermedio que vuelve funcional el ciclo, y M3 estudia la sensibilidad a su alrededor.
... A32: Falso convergido: el solver dijo que convergió, pero no es un ciclo real (no cuenta)

Sheet Nomenclatura
A1: Cómo se numera todo (como los capítulos de un informe)
A3: • PREGUNTA (1 a 6): qué queremos saber. El anexo A es una curiosidad que no entra en las conclusiones.
A4: • ESTUDIO (por ejemplo 2.4): un barrido que responde esa pregunta. El primer número es la pregunta.
A5: • PARTE (por ejemplo 2.4a): cuando un estudio tiene partes con datos fijos distintos, cada una lleva una letra. REGLA: solo se comparan puntos de la misma parte.
A6: • Tabla 4.1-1, Figura 3.2-2: tablas y figuras van numeradas por estudio (4.1-1 = tabla 1 del estudio 4.1). Las de síntesis de toda la campaña llevan S (Tabla S-4, Figura S-1).
A7: • En cada estudio, la Tabla x.y-1 son las condiciones (qué quedó fijo y qué se barrió), la x.y-2 el conteo de corridas por clase y las siguientes, los resultados.
A8: • El 'código de origen' (M05, KF-M05-3, B09-3…) es el nombre interno de los archivos de cálculo; solo sirve para rastrear un dato hasta su CSV.
A10: Pregunta | B10: Estudio | C10: Nombre del estudio | D10: Partes (letra = datos fijos distintos) | E10: Código de origen
A11: 1 · ¿Funciona el ciclo con los datos del profesor? | B11: 1.1 | C11: Repetir el caso del profesor | D11: 1.1a: punto del profesor | 1.1b: solo P_alta | 1.1c: solo x_b | 1.1d: temperatura ambiente hora a hora | E11: M01
A12: 2 · ¿Qué es lo mínimo que hay que cambiar para que funcione? | B12: 2.1 | C12: Un solo cambio | D12: una variable a la vez | E12: M02-N1
A13: 2 · ¿Qué es lo mínimo que hay que cambiar para que funcione? | B13: 2.2 | C13: Dos cambios | D13: 2.2a: conservar la fuente (ε_HRVG × P_baja) | 2.2b: bajar la fuente (T_fuente × P_baja) | E13: M02-N2
A14: 2 · ¿Qué es lo mínimo que hay que cambiar para que funcione? | B14: 2.3 | C14: Dos cambios con η y ε en 0.40–0.95 | D14: 2.3a: un cambio | 2.3b: ε_HRVG × ε_cond | 2.3c: ε_HRVG × P_baja | 2.3d: T_fuente × ε_cond | E14: M02R
A15: 2 · ¿Qué es lo mínimo que hay que cambiar para que funcione? | B15: 2.4 | C15: Sumidero más frío | D15: 2.4a: fuente a 403 K | 2.4b: fuente a 420 K | 2.4c: ε_HRVG = 0.40 (fuente del profesor) | 2.4d: datos exactos del profesor | E15: M02S
A16: 3 · ¿Qué variables importan y cuánto? | B16: 3.1 | C16: Sensibilidad local alrededor de A* | D16: alrededor de A* | E16: M03
A17: 3 · ¿Qué variables importan y cuánto? | B17: 3.2 | C17: Sensibilidad global (500 puntos) | D17: muestra de 300 puntos | muestra de 200 puntos | E17: M04, M04b
A18: 3 · ¿Qué variables importan y cuánto? | B18: 3.3 | C18: P_baja alta (1500–2500 kPa) | D18: P_baja de 1500 a 2500 kPa | E18: M04c
A19: 4 · ¿Qué datos del profesor se pueden conservar? | B19: 4.1 | C19: Escenarios de conservación | D19: 4.1a: conserva sus temperaturas | 4.1b: conserva sus presiones | 4.1c: conserva sus presiones y su clima | 4.1d: conserva su P_alta y sus temperaturas | 4.1e: conserva su fuente y su x_b | E19: M05
A20: 4 · ¿Qué datos del profesor se pueden conservar? | B20: 4.2 | C20: Mapa con las presiones del profesor | D20: presiones del profesor, malla T_fuente × ε_cond × clima | E20: M05c
A21: 4 · ¿Qué datos del profesor se pueden conservar? | B21: 4.3 | C21: Escalera de conservación | D21: rondas 0 a 3; cada conjunto se nombra con sus variables (p. ej. 4.3 x_b+P_alta) | E21: M09
... A25: A · Anexo: equipos fuera del rango realista (no entra en las conclusiones) | B25: A.1 | C25: Equipos fuera del rango realista | D25: η y ε de 0.20 a 0.99 | E25: M08

Sheet Tablero
A1: Tablero de resultados — elija un estudio o una parte en B2
A2: Estudio / parte: | B2: 3.2 · Sensibilidad global (500 puntos) | C2: =INDEX(Aux_tablero!$B$11:$AY$11,MATCH($B$2,Aux_tablero!$B$1:$AY$1,0))
D4: Corridas | E4: Genuinas | F4: KALINA | G4: KALINA confiables | H4: η máx. KALINA [%] | I4: Criterio que más bloquea | K4: Eje X: | L4: =INDEX(Aux_tablero!$B$8:$AY$8,MATCH($B$2,Aux_tablero!$B$1:$AY$1,0)) | AC4: xK | AD4: yK | AE4: xC | AF4: yC | AG4: xI | AH4: yI | AI4: xN | AJ4: yN
D5: =INDEX(Aux_tablero!$B$2:$AY$2,MATCH($B$2,Aux_tablero!$B$1:$AY$1,0)) | E5: =INDEX(Aux_tablero!$B$3:$AY$3,MATCH($B$2,Aux_tablero!$B$1:$AY$1,0)) | F5: =INDEX(Aux_tablero!$B$4:$AY$4,MATCH($B$2,Aux_tablero!$B$1:$AY$1,0)) | G5: =INDEX(Aux_tablero!$B$5:$AY$5,MATCH($B$2,Aux_tablero!$B$1:$AY$1,0)) | H5: =INDEX(Aux_tablero!$B$6:$AY$6,MATCH($B$2,Aux_tablero!$B$1:$AY$1,0)) | I5: =INDEX(Aux_tablero!$B$7:$AY$7,MATCH($B$2,Aux_tablero!$B$1:$AY$1,0)) | K5: Eje Y: | L5: =INDEX(Aux_tablero!$B$9:$AY$9,MATCH($B$2,Aux_tablero!$B$1:$AY$1,0)) | Z5: KALINA | AA5: =INDEX(Aux_tablero!$B$12:$AY$12,MATCH($B$2,Aux_tablero!$B$1:$AY$1,0)) | AC5: =IFERROR(IF(INDEX(Aux_puntos!$A$2:$OJ$901,1,MATCH($B$2&"|xK",Aux_puntos!$1:$1,0))="",NA(),INDEX(Aux_puntos!$A$2:$OJ$901,1,MATCH($B$2&"|xK",Aux_puntos!$1:$1,0))),NA()) | AD5: =IFERROR(IF(INDEX(Aux_puntos!$A$2:$OJ$901,1,MATCH($B$2&"|yK",Aux_puntos!$1:$1,0))="",NA(),INDEX(Aux_puntos!$A$2:$OJ$901,1,MATCH($B$2&"|yK",Aux_puntos!$1:$1,0))),NA()) | AE5: =IFERROR(IF(INDEX(Aux_puntos!$A$2:$OJ$901,1,MATCH($B$2&"|xC",Aux_puntos!$1:$1,0))="",NA(),INDEX(Aux_puntos!$A$2:$OJ$901,1,MATCH($B$2&"|xC",Aux_puntos!$1:$1,0))),NA()) | AF5: =IFERROR(IF(INDEX(Aux_puntos!$A$2:$OJ$901,1,MATCH($B$2&"|yC",Aux_puntos!$1:$1,0))="",NA(),INDEX(Aux_puntos!$A$2:$OJ$901,1,MATCH($B$2&"|yC",Aux_puntos!$1:$1,0))),NA()) | AG5: =IFERROR(IF(INDEX(Aux_puntos!$A$2:$OJ$901,1,MATCH($B$2&"|xI",Aux_puntos!$1:$1,0))="",NA(),INDEX(Aux_puntos!$A$2:$OJ$901,1,MATCH($B$2&"|xI",Aux_puntos!$1:$1,0))),NA()) | AH5: =IFERROR(IF(INDEX(Aux_puntos!$A$2:$OJ$901,1,MATCH($B$2&"|yI",Aux_puntos!$1:$1,0))="",NA(),INDEX(Aux_puntos!$A$2:$OJ$901,1,MATCH($B$2&"|yI",Aux_puntos!$1:$1,0))),NA()) | AI5: =IFERROR(IF(INDEX(Aux_puntos!$A$2:$OJ$901,1,MATCH($B$2&"|xN",Aux_puntos!$1:$1,0))="",NA(),INDEX(Aux_puntos!$A$2:$OJ$901,1,MATCH($B$2&"|xN",Aux_puntos!$1:$1,0))),NA()) | AJ5: =IFERROR(IF(INDEX(Aux_puntos!$A$2:$OJ$901,1,MATCH($B$2&"|yN",Aux_puntos!$1:$1,0))="",NA(),INDEX(Aux_puntos!$A$2:$OJ$901,1,MATCH($B$2&"|yN",Aux_puntos!$1:$1,0))),NA())
Z6: Corregible | AA6: =INDEX(Aux_tablero!$B$13:$AY$13,MATCH($B$2,Aux_tablero!$B$1:$AY$1,0)) | AC6: =IFERROR(IF(INDEX(Aux_puntos!$A$2:$OJ$901,2,MATCH($B$2&"|xK",Aux_puntos!$1:$1,0))="",NA(),INDEX(Aux_puntos!$A$2:$OJ$901,2,MATCH($B$2&"|xK",Aux_puntos!$1:$1,0))),NA()) | AD6: =IFERROR(IF(INDEX(Aux_puntos!$A$2:$OJ$901,2,MATCH($B$2&"|yK",Aux_puntos!$1:$1,0))="",NA(),INDEX(Aux_puntos!$A$2:$OJ$901,2,MATCH($B$2&"|yK",Aux_puntos!$1:$1,0))),NA()) | AE6: =IFERROR(IF(INDEX(Aux_puntos!$A$2:$OJ$901,2,MATCH($B$2&"|xC",Aux_puntos!$1:$1,0))="",NA(),INDEX(Aux_puntos!$A$2:$OJ$901,2,MATCH($B$2&"|xC",Aux_puntos!$1:$1,0))),NA()) | AF6: =IFERROR(IF(INDEX(Aux_puntos!$A$2:$OJ$901,2,MATCH($B$2&"|yC",Aux_puntos!$1:$1,0))="",NA(),INDEX(Aux_puntos!$A$2:$OJ$901,2,MATCH($B$2&"|yC",Aux_puntos!$1:$1,0))),NA()) | AG6: =IFERROR(IF(INDEX(Aux_puntos!$A$2:$OJ$901,2,MATCH($B$2&"|xI",Aux_puntos!$1:$1,0))="",NA(),INDEX(Aux_puntos!$A$2:$OJ$901,2,MATCH($B$2&"|xI",Aux_puntos!$1:$1,0))),NA()) | AH6: =IFERROR(IF(INDEX(Aux_puntos!$A$2:$OJ$901,2,MATCH($B$2&"|yI",Aux_puntos!$1:$1,0))="",NA(),INDEX(Aux_puntos!$A$2:$OJ$901,2,MATCH($B$2&"|yI",Aux_puntos!$1:$1,0))),NA()) | AI6: =IFERROR(IF(INDEX(Aux_puntos!$A$2:$OJ$901,2,MATCH($B$2&"|xN",Aux_puntos!$1:$1,0))="",NA(),INDEX(Aux_puntos!$A$2:$OJ$901,2,MATCH($B$2&"|xN",Aux_puntos!$1:$1,0))),NA()) | AJ6: =IFERROR(IF(INDEX(Aux_puntos!$A$2:$OJ$901,2,MATCH($B$2&"|yN",Aux_puntos!$1:$1,0))="",NA(),INDEX(Aux_puntos!$A$2:$OJ$901,2,MATCH($B$2&"|yN",Aux_puntos!$1:$1,0))),NA())
A7: Condiciones (datos fijos y barridos) | Z7: Inviable | AA7: =INDEX(Aux_tablero!$B$14:$AY$14,MATCH($B$2,Aux_tablero!$B$1:$AY$1,0)) | AC7: =IFERROR(IF(INDEX(Aux_puntos!$A$2:$OJ$901,3,MATCH($B$2&"|xK",Aux_puntos!$1:$1,0))="",NA(),INDEX(Aux_puntos!$A$2:$OJ$901,3,MATCH($B$2&"|xK",Aux_puntos!$1:$1,0))),NA()) | AD7: =IFERROR(IF(INDEX(Aux_puntos!$A$2:$OJ$901,3,MATCH($B$2&"|yK",Aux_puntos!$1:$1,0))="",NA(),INDEX(Aux_puntos!$A$2:$OJ$901,3,MATCH($B$2&"|yK",Aux_puntos!$1:$1,0))),NA()) | AE7: =IFERROR(IF(INDEX(Aux_puntos!$A$2:$OJ$901,3,MATCH($B$2&"|xC",Aux_puntos!$1:$1,0))="",NA(),INDEX(Aux_puntos!$A$2:$OJ$901,3,MATCH($B$2&"|xC",Aux_puntos!$1:$1,0))),NA()) | AF7: =IFERROR(IF(INDEX(Aux_puntos!$A$2:$OJ$901,3,MATCH($B$2&"|yC",Aux_puntos!$1:$1,0))="",NA(),INDEX(Aux_puntos!$A$2:$OJ$901,3,MATCH($B$2&"|yC",Aux_puntos!$1:$1,0))),NA()) | AG7: =IFERROR(IF(INDEX(Aux_puntos!$A$2:$OJ$901,3,MATCH($B$2&"|xI",Aux_puntos!$1:$1,0))="",NA(),INDEX(Aux_puntos!$A$2:$OJ$901,3,MATCH($B$2&"|xI",Aux_puntos!$1:$1,0))),NA()) | AH7: =IFERROR(IF(INDEX(Aux_puntos!$A$2:$OJ$901,3,MATCH($B$2&"|yI",Aux_puntos!$1:$1,0))="",NA(),INDEX(Aux_puntos!$A$2:$OJ$901,3,MATCH($B$2&"|yI",Aux_puntos!$1:$1,0))),NA()) | AI7: =IFERROR(IF(INDEX(Aux_puntos!$A$2:$OJ$901,3,MATCH($B$2&"|xN",Aux_puntos!$1:$1,0))="",NA(),INDEX(Aux_puntos!$A$2:$OJ$901,3,MATCH($B$2&"|xN",Aux_puntos!$1:$1,0))),NA()) | AJ7: =IFERROR(IF(INDEX(Aux_puntos!$A$2:$OJ$901,3,MATCH($B$2&"|yN",Aux_puntos!$1:$1,0))="",NA(),INDEX(Aux_puntos!$A$2:$OJ$901,3,MATCH($B$2&"|yN",Aux_puntos!$1:$1,0))),NA())
A8: Temperatura de la fuente, T_fuente [K] | B8: =INDEX(Aux_tablero!$B$21:$AY$21,MATCH($B$2,Aux_tablero!$B$1:$AY$1,0)) | Z8: No convergió | AA8: =INDEX(Aux_tablero!$B$15:$AY$15,MATCH($B$2,Aux_tablero!$B$1:$AY$1,0)) | AC8: =IFERROR(IF(INDEX(Aux_puntos!$A$2:$OJ$901,4,MATCH($B$2&"|xK",Aux_puntos!$1:$1,0))="",NA(),INDEX(Aux_puntos!$A$2:$OJ$901,4,MATCH($B$2&"|xK",Aux_puntos!$1:$1,0))),NA()) | AD8: =IFERROR(IF(INDEX(Aux_puntos!$A$2:$OJ$901,4,MATCH($B$2&"|yK",Aux_puntos!$1:$1,0))="",NA(),INDEX(Aux_puntos!$A$2:$OJ$901,4,MATCH($B$2&"|yK",Aux_puntos!$1:$1,0))),NA()) | AE8: =IFERROR(IF(INDEX(Aux_puntos!$A$2:$OJ$901,4,MATCH($B$2&"|xC",Aux_puntos!$1:$1,0))="",NA(),INDEX(Aux_puntos!$A$2:$OJ$901,4,MATCH($B$2&"|xC",Aux_puntos!$1:$1,0))),NA()) | AF8: =IFERROR(IF(INDEX(Aux_puntos!$A$2:$OJ$901,4,MATCH($B$2&"|yC",Aux_puntos!$1:$1,0))="",NA(),INDEX(Aux_puntos!$A$2:$OJ$901,4,MATCH($B$2&"|yC",Aux_puntos!$1:$1,0))),NA()) | AG8: =IFERROR(IF(INDEX(Aux_puntos!$A$2:$OJ$901,4,MATCH($B$2&"|xI",Aux_puntos!$1:$1,0))="",NA(),INDEX(Aux_puntos!$A$2:$OJ$901,4,MATCH($B$2&"|xI",Aux_puntos!$1:$1,0))),NA()) | AH8: =IFERROR(IF(INDEX(Aux_puntos!$A$2:$OJ$901,4,MATCH($B$2&"|yI",Aux_puntos!$1:$1,0))="",NA(),INDEX(Aux_puntos!$A$2:$OJ$901,4,MATCH($B$2&"|yI",Aux_puntos!$1:$1,0))),NA()) | AI8: =IFERROR(IF(INDEX(Aux_puntos!$A$2:$OJ$901,4,MATCH($B$2&"|xN",Aux_puntos!$1:$1,0))="",NA(),INDEX(Aux_puntos!$A$2:$OJ$901,4,MATCH($B$2&"|xN",Aux_puntos!$1:$1,0))),NA()) | AJ8: =IFERROR(IF(INDEX(Aux_puntos!$A$2:$OJ$901,4,MATCH($B$2&"|yN",Aux_puntos!$1:$1,0))="",NA(),INDEX(Aux_puntos!$A$2:$OJ$901,4,MATCH($B$2&"|yN",Aux_puntos!$1:$1,0))),NA())
A9: Temperatura del sumidero, T_sumidero [K] | B9: =INDEX(Aux_tablero!$B$22:$AY$22,MATCH($B$2,Aux_tablero!$B$1:$AY$1,0)) | Z9: Falso convergido | AA9: =INDEX(Aux_tablero!$B$16:$AY$16,MATCH($B$2,Aux_tablero!$B$1:$AY$1,0)) | AC9: =IFERROR(IF(INDEX(Aux_puntos!$A$2:$OJ$901,5,MATCH($B$2&"|xK",Aux_puntos!$1:$1,0))="",NA(),INDEX(Aux_puntos!$A$2:$OJ$901,5,MATCH($B$2&"|xK",Aux_puntos!$1:$1,0))),NA()) | AD9: =IFERROR(IF(INDEX(Aux_puntos!$A$2:$OJ$901,5,MATCH($B$2&"|yK",Aux_puntos!$1:$1,0))="",NA(),INDEX(Aux_puntos!$A$2:$OJ$901,5,MATCH($B$2&"|yK",Aux_puntos!$1:$1,0))),NA()) | AE9: =IFERROR(IF(INDEX(Aux_puntos!$A$2:$OJ$901,5,MATCH($B$2&"|xC",Aux_puntos!$1:$1,0))="",NA(),INDEX(Aux_puntos!$A$2:$OJ$901,5,MATCH($B$2&"|xC",Aux_puntos!$1:$1,0))),NA()) | AF9: =IFERROR(IF(INDEX(Aux_puntos!$A$2:$OJ$901,5,MATCH($B$2&"|yC",Aux_puntos!$1:$1,0))="",NA(),INDEX(Aux_puntos!$A$2:$OJ$901,5,MATCH($B$2&"|yC",Aux_puntos!$1:$1,0))),NA()) | AG9: =IFERROR(IF(INDEX(Aux_puntos!$A$2:$OJ$901,5,MATCH($B$2&"|xI",Aux_puntos!$1:$1,0))="",NA(),INDEX(Aux_puntos!$A$2:$OJ$901,5,MATCH($B$2&"|xI",Aux_puntos!$1:$1,0))),NA()) | AH9: =IFERROR(IF(INDEX(Aux_puntos!$A$2:$OJ$901,5,MATCH($B$2&"|yI",Aux_puntos!$1:$1,0))="",NA(),INDEX(Aux_puntos!$A$2:$OJ$901,5,MATCH($B$2&"|yI",Aux_puntos!$1:$1,0))),NA()) | AI9: =IFERROR(IF(INDEX(Aux_puntos!$A$2:$OJ$901,5,MATCH($B$2&"|xN",Aux_puntos!$1:$1,0))="",NA(),INDEX(Aux_puntos!$A$2:$OJ$901,5,MATCH($B$2&"|xN",Aux_puntos!$1:$1,0))),NA()) | AJ9: =IFERROR(IF(INDEX(Aux_puntos!$A$2:$OJ$901,5,MATCH($B$2&"|yN",Aux_puntos!$1:$1,0))="",NA(),INDEX(Aux_puntos!$A$2:$OJ$901,5,MATCH($B$2&"|yN",Aux_puntos!$1:$1,0))),NA())
A10: Presión de alta, P_alta [kPa] | B10: =INDEX(Aux_tablero!$B$23:$AY$23,MATCH($B$2,Aux_tablero!$B$1:$AY$1,0)) | AC10: =IFERROR(IF(INDEX(Aux_puntos!$A$2:$OJ$901,6,MATCH($B$2&"|xK",Aux_puntos!$1:$1,0))="",NA(),INDEX(Aux_puntos!$A$2:$OJ$901,6,MATCH($B$2&"|xK",Aux_puntos!$1:$1,0))),NA()) | AD10: =IFERROR(IF(INDEX(Aux_puntos!$A$2:$OJ$901,6,MATCH($B$2&"|yK",Aux_puntos!$1:$1,0))="",NA(),INDEX(Aux_puntos!$A$2:$OJ$901,6,MATCH($B$2&"|yK",Aux_puntos!$1:$1,0))),NA()) | AE10: =IFERROR(IF(INDEX(Aux_puntos!$A$2:$OJ$901,6,MATCH($B$2&"|xC",Aux_puntos!$1:$1,0))="",NA(),INDEX(Aux_puntos!$A$2:$OJ$901,6,MATCH($B$2&"|xC",Aux_puntos!$1:$1,0))),NA()) | AF10: =IFERROR(IF(INDEX(Aux_puntos!$A$2:$OJ$901,6,MATCH($B$2&"|yC",Aux_puntos!$1:$1,0))="",NA(),INDEX(Aux_puntos!$A$2:$OJ$901,6,MATCH($B$2&"|yC",Aux_puntos!$1:$1,0))),NA()) | AG10: =IFERROR(IF(INDEX(Aux_puntos!$A$2:$OJ$901,6,MATCH($B$2&"|xI",Aux_puntos!$1:$1,0))="",NA(),INDEX(Aux_puntos!$A$2:$OJ$901,6,MATCH($B$2&"|xI",Aux_puntos!$1:$1,0))),NA()) | AH10: =IFERROR(IF(INDEX(Aux_puntos!$A$2:$OJ$901,6,MATCH($B$2&"|yI",Aux_puntos!$1:$1,0))="",NA(),INDEX(Aux_puntos!$A$2:$OJ$901,6,MATCH($B$2&"|yI",Aux_puntos!$1:$1,0))),NA()) | AI10: =IFERROR(IF(INDEX(Aux_puntos!$A$2:$OJ$901,6,MATCH($B$2&"|xN",Aux_puntos!$1:$1,0))="",NA(),INDEX(Aux_puntos!$A$2:$OJ$901,6,MATCH($B$2&"|xN",Aux_puntos!$1:$1,0))),NA()) | AJ10: =IFERROR(IF(INDEX(Aux_puntos!$A$2:$OJ$901,6,MATCH($B$2&"|yN",Aux_puntos!$1:$1,0))="",NA(),INDEX(Aux_puntos!$A$2:$OJ$901,6,MATCH($B$2&"|yN",Aux_puntos!$1:$1,0))),NA())
A11: Presión de baja, P_baja [kPa] | B11: =INDEX(Aux_tablero!$B$24:$AY$24,MATCH($B$2,Aux_tablero!$B$1:$AY$1,0)) | AC11: =IFERROR(IF(INDEX(Aux_puntos!$A$2:$OJ$901,7,MATCH($B$2&"|xK",Aux_puntos!$1:$1,0))="",NA(),INDEX(Aux_puntos!$A$2:$OJ$901,7,MATCH($B$2&"|xK",Aux_puntos!$1:$1,0))),NA()) | AD11: =IFERROR(IF(INDEX(Aux_puntos!$A$2:$OJ$901,7,MATCH($B$2&"|yK",Aux_puntos!$1:$1,0))="",NA(),INDEX(Aux_puntos!$A$2:$OJ$901,7,MATCH($B$2&"|yK",Aux_puntos!$1:$1,0))),NA()) | AE11: =IFERROR(IF(INDEX(Aux_puntos!$A$2:$OJ$901,7,MATCH($B$2&"|xC",Aux_puntos!$1:$1,0))="",NA(),INDEX(Aux_puntos!$A$2:$OJ$901,7,MATCH($B$2&"|xC",Aux_puntos!$1:$1,0))),NA()) | AF11: =IFERROR(IF(INDEX(Aux_puntos!$A$2:$OJ$901,7,MATCH($B$2&"|yC",Aux_puntos!$1:$1,0))="",NA(),INDEX(Aux_puntos!$A$2:$OJ$901,7,MATCH($B$2&"|yC",Aux_puntos!$1:$1,0))),NA()) | AG11: =IFERROR(IF(INDEX(Aux_puntos!$A$2:$OJ$901,7,MATCH($B$2&"|xI",Aux_puntos!$1:$1,0))="",NA(),INDEX(Aux_puntos!$A$2:$OJ$901,7,MATCH($B$2&"|xI",Aux_puntos!$1:$1,0))),NA()) | AH11: =IFERROR(IF(INDEX(Aux_puntos!$A$2:$OJ$901,7,MATCH($B$2&"|yI",Aux_puntos!$1:$1,0))="",NA(),INDEX(Aux_puntos!$A$2:$OJ$901,7,MATCH($B$2&"|yI",Aux_puntos!$1:$1,0))),NA()) | AI11: =IFERROR(IF(INDEX(Aux_puntos!$A$2:$OJ$901,7,MATCH($B$2&"|xN",Aux_puntos!$1:$1,0))="",NA(),INDEX(Aux_puntos!$A$2:$OJ$901,7,MATCH($B$2&"|xN",Aux_puntos!$1:$1,0))),NA()) | AJ11: =IFERROR(IF(INDEX(Aux_puntos!$A$2:$OJ$901,7,MATCH($B$2&"|yN",Aux_puntos!$1:$1,0))="",NA(),INDEX(Aux_puntos!$A$2:$OJ$901,7,MATCH($B$2&"|yN",Aux_puntos!$1:$1,0))),NA())
A12: Fracción de amoníaco de la mezcla base, x_b [–] | B12: =INDEX(Aux_tablero!$B$25:$AY$25,MATCH($B$2,Aux_tablero!$B$1:$AY$1,0)) | Z12: O1 título | AA12: =INDEX(Aux_tablero!$B$17:$AY$17,MATCH($B$2,Aux_tablero!$B$1:$AY$1,0)) | AC12: =IFERROR(IF(INDEX(Aux_puntos!$A$2:$OJ$901,8,MATCH($B$2&"|xK",Aux_puntos!$1:$1,0))="",NA(),INDEX(Aux_puntos!$A$2:$OJ$901,8,MATCH($B$2&"|xK",Aux_puntos!$1:$1,0))),NA()) | AD12: =IFERROR(IF(INDEX(Aux_puntos!$A$2:$OJ$901,8,MATCH($B$2&"|yK",Aux_puntos!$1:$1,0))="",NA(),INDEX(Aux_puntos!$A$2:$OJ$901,8,MATCH($B$2&"|yK",Aux_puntos!$1:$1,0))),NA()) | AE12: =IFERROR(IF(INDEX(Aux_puntos!$A$2:$OJ$901,8,MATCH($B$2&"|xC",Aux_puntos!$1:$1,0))="",NA(),INDEX(Aux_puntos!$A$2:$OJ$901,8,MATCH($B$2&"|xC",Aux_puntos!$1:$1,0))),NA()) | AF12: =IFERROR(IF(INDEX(Aux_puntos!$A$2:$OJ$901,8,MATCH($B$2&"|yC",Aux_puntos!$1:$1,0))="",NA(),INDEX(Aux_puntos!$A$2:$OJ$901,8,MATCH($B$2&"|yC",Aux_puntos!$1:$1,0))),NA()) | AG12: =IFERROR(IF(INDEX(Aux_puntos!$A$2:$OJ$901,8,MATCH($B$2&"|xI",Aux_puntos!$1:$1,0))="",NA(),INDEX(Aux_puntos!$A$2:$OJ$901,8,MATCH($B$2&"|xI",Aux_puntos!$1:$1,0))),NA()) | AH12: =IFERROR(IF(INDEX(Aux_puntos!$A$2:$OJ$901,8,MATCH($B$2&"|yI",Aux_puntos!$1:$1,0))="",NA(),INDEX(Aux_puntos!$A$2:$OJ$901,8,MATCH($B$2&"|yI",Aux_puntos!$1:$1,0))),NA()) | AI12: =IFERROR(IF(INDEX(Aux_puntos!$A$2:$OJ$901,8,MATCH($B$2&"|xN",Aux_puntos!$1:$1,0))="",NA(),INDEX(Aux_puntos!$A$2:$OJ$901,8,MATCH($B$2&"|xN",Aux_puntos!$1:$1,0))),NA()) | AJ12: =IFERROR(IF(INDEX(Aux_puntos!$A$2:$OJ$901,8,MATCH($B$2&"|yN",Aux_puntos!$1:$1,0))="",NA(),INDEX(Aux_puntos!$A$2:$OJ$901,8,MATCH($B$2&"|yN",Aux_puntos!$1:$1,0))),NA())
A13: Flujo másico base, m_b [kg/s] | B13: =INDEX(Aux_tablero!$B$26:$AY$26,MATCH($B$2,Aux_tablero!$B$1:$AY$1,0)) | Z13: O2 cavitación | AA13: =INDEX(Aux_tablero!$B$18:$AY$18,MATCH($B$2,Aux_tablero!$B$1:$AY$1,0)) | AC13: =IFERROR(IF(INDEX(Aux_puntos!$A$2:$OJ$901,9,MATCH($B$2&"|xK",Aux_puntos!$1:$1,0))="",NA(),INDEX(Aux_puntos!$A$2:$OJ$901,9,MATCH($B$2&"|xK",Aux_puntos!$1:$1,0))),NA()) | AD13: =IFERROR(IF(INDEX(Aux_puntos!$A$2:$OJ$901,9,MATCH($B$2&"|yK",Aux_puntos!$1:$1,0))="",NA(),INDEX(Aux_puntos!$A$2:$OJ$901,9,MATCH($B$2&"|yK",Aux_puntos!$1:$1,0))),NA()) | AE13: =IFERROR(IF(INDEX(Aux_puntos!$A$2:$OJ$901,9,MATCH($B$2&"|xC",Aux_puntos!$1:$1,0))="",NA(),INDEX(Aux_puntos!$A$2:$OJ$901,9,MATCH($B$2&"|xC",Aux_puntos!$1:$1,0))),NA()) | AF13: =IFERROR(IF(INDEX(Aux_puntos!$A$2:$OJ$901,9,MATCH($B$2&"|yC",Aux_puntos!$1:$1,0))="",NA(),INDEX(Aux_puntos!$A$2:$OJ$901,9,MATCH($B$2&"|yC",Aux_puntos!$1:$1,0))),NA()) | AG13: =IFERROR(IF(INDEX(Aux_puntos!$A$2:$OJ$901,9,MATCH($B$2&"|xI",Aux_puntos!$1:$1,0))="",NA(),INDEX(Aux_puntos!$A$2:$OJ$901,9,MATCH($B$2&"|xI",Aux_puntos!$1:$1,0))),NA()) | AH13: =IFERROR(IF(INDEX(Aux_puntos!$A$2:$OJ$901,9,MATCH($B$2&"|yI",Aux_puntos!$1:$1,0))="",NA(),INDEX(Aux_puntos!$A$2:$OJ$901,9,MATCH($B$2&"|yI",Aux_puntos!$1:$1,0))),NA()) | AI13: =IFERROR(IF(INDEX(Aux_puntos!$A$2:$OJ$901,9,MATCH($B$2&"|xN",Aux_puntos!$1:$1,0))="",NA(),INDEX(Aux_puntos!$A$2:$OJ$901,9,MATCH($B$2&"|xN",Aux_puntos!$1:$1,0))),NA()) | AJ13: =IFERROR(IF(INDEX(Aux_puntos!$A$2:$OJ$901,9,MATCH($B$2&"|yN",Aux_puntos!$1:$1,0))="",NA(),INDEX(Aux_puntos!$A$2:$OJ$901,9,MATCH($B$2&"|yN",Aux_puntos!$1:$1,0))),NA())
A14: Eficiencia isentrópica de la turbina, η_t [–] | B14: =INDEX(Aux_tablero!$B$27:$AY$27,MATCH($B$2,Aux_tablero!$B$1:$AY$1,0)) | Z14: O3 trabajo neto | AA14: =INDEX(Aux_tablero!$B$19:$AY$19,MATCH($B$2,Aux_tablero!$B$1:$AY$1,0)) | AC14: =IFERROR(IF(INDEX(Aux_puntos!$A$2:$OJ$901,10,MATCH($B$2&"|xK",Aux_puntos!$1:$1,0))="",NA(),INDEX(Aux_puntos!$A$2:$OJ$901,10,MATCH($B$2&"|xK",Aux_puntos!$1:$1,0))),NA()) | AD14: =IFERROR(IF(INDEX(Aux_puntos!$A$2:$OJ$901,10,MATCH($B$2&"|yK",Aux_puntos!$1:$1,0))="",NA(),INDEX(Aux_puntos!$A$2:$OJ$901,10,MATCH($B$2&"|yK",Aux_puntos!$1:$1,0))),NA()) | AE14: =IFERROR(IF(INDEX(Aux_puntos!$A$2:$OJ$901,10,MATCH($B$2&"|xC",Aux_puntos!$1:$1,0))="",NA(),INDEX(Aux_puntos!$A$2:$OJ$901,10,MATCH($B$2&"|xC",Aux_puntos!$1:$1,0))),NA()) | AF14: =IFERROR(IF(INDEX(Aux_puntos!$A$2:$OJ$901,10,MATCH($B$2&"|yC",Aux_puntos!$1:$1,0))="",NA(),INDEX(Aux_puntos!$A$2:$OJ$901,10,MATCH($B$2&"|yC",Aux_puntos!$1:$1,0))),NA()) | AG14: =IFERROR(IF(INDEX(Aux_puntos!$A$2:$OJ$901,10,MATCH($B$2&"|xI",Aux_puntos!$1:$1,0))="",NA(),INDEX(Aux_puntos!$A$2:$OJ$901,10,MATCH($B$2&"|xI",Aux_puntos!$1:$1,0))),NA()) | AH14: =IFERROR(IF(INDEX(Aux_puntos!$A$2:$OJ$901,10,MATCH($B$2&"|yI",Aux_puntos!$1:$1,0))="",NA(),INDEX(Aux_puntos!$A$2:$OJ$901,10,MATCH($B$2&"|yI",Aux_puntos!$1:$1,0))),NA()) | AI14: =IFERROR(IF(INDEX(Aux_puntos!$A$2:$OJ$901,10,MATCH($B$2&"|xN",Aux_puntos!$1:$1,0))="",NA(),INDEX(Aux_puntos!$A$2:$OJ$901,10,MATCH($B$2&"|xN",Aux_puntos!$1:$1,0))),NA()) | AJ14: =IFERROR(IF(INDEX(Aux_puntos!$A$2:$OJ$901,10,MATCH($B$2&"|yN",Aux_puntos!$1:$1,0))="",NA(),INDEX(Aux_puntos!$A$2:$OJ$901,10,MATCH($B$2&"|yN",Aux_puntos!$1:$1,0))),NA())
A15: Eficiencia isentrópica de la bomba, η_p [–] | B15: =INDEX(Aux_tablero!$B$28:$AY$28,MATCH($B$2,Aux_tablero!$B$1:$AY$1,0)) | Z15: O5 separador | AA15: =INDEX(Aux_tablero!$B$20:$AY$20,MATCH($B$2,Aux_tablero!$B$1:$AY$1,0)) | AC15: =IFERROR(IF(INDEX(Aux_puntos!$A$2:$OJ$901,11,MATCH($B$2&"|xK",Aux_puntos!$1:$1,0))="",NA(),INDEX(Aux_puntos!$A$2:$OJ$901,11,MATCH($B$2&"|xK",Aux_puntos!$1:$1,0))),NA()) | AD15: =IFERROR(IF(INDEX(Aux_puntos!$A$2:$OJ$901,11,MATCH($B$2&"|yK",Aux_puntos!$1:$1,0))="",NA(),INDEX(Aux_puntos!$A$2:$OJ$901,11,MATCH($B$2&"|yK",Aux_puntos!$1:$1,0))),NA()) | AE15: =IFERROR(IF(INDEX(Aux_puntos!$A$2:$OJ$901,11,MATCH($B$2&"|xC",Aux_puntos!$1:$1,0))="",NA(),INDEX(Aux_puntos!$A$2:$OJ$901,11,MATCH($B$2&"|xC",Aux_puntos!$1:$1,0))),NA()) | AF15: =IFERROR(IF(INDEX(Aux_puntos!$A$2:$OJ$901,11,MATCH($B$2&"|yC",Aux_puntos!$1:$1,0))="",NA(),INDEX(Aux_puntos!$A$2:$OJ$901,11,MATCH($B$2&"|yC",Aux_puntos!$1:$1,0))),NA()) | AG15: =IFERROR(IF(INDEX(Aux_puntos!$A$2:$OJ$901,11,MATCH($B$2&"|xI",Aux_puntos!$1:$1,0))="",NA(),INDEX(Aux_puntos!$A$2:$OJ$901,11,MATCH($B$2&"|xI",Aux_puntos!$1:$1,0))),NA()) | AH15: =IFERROR(IF(INDEX(Aux_puntos!$A$2:$OJ$901,11,MATCH($B$2&"|yI",Aux_puntos!$1:$1,0))="",NA(),INDEX(Aux_puntos!$A$2:$OJ$901,11,MATCH($B$2&"|yI",Aux_puntos!$1:$1,0))),NA()) | AI15: =IFERROR(IF(INDEX(Aux_puntos!$A$2:$OJ$901,11,MATCH($B$2&"|xN",Aux_puntos!$1:$1,0))="",NA(),INDEX(Aux_puntos!$A$2:$OJ$901,11,MATCH($B$2&"|xN",Aux_puntos!$1:$1,0))),NA()) | AJ15: =IFERROR(IF(INDEX(Aux_puntos!$A$2:$OJ$901,11,MATCH($B$2&"|yN",Aux_puntos!$1:$1,0))="",NA(),INDEX(Aux_puntos!$A$2:$OJ$901,11,MATCH($B$2&"|yN",Aux_puntos!$1:$1,0))),NA())
A16: Efectividad del generador de vapor, ε_HRVG [–] | B16: =INDEX(Aux_tablero!$B$29:$AY$29,MATCH($B$2,Aux_tablero!$B$1:$AY$1,0)) | AC16: =IFERROR(IF(INDEX(Aux_puntos!$A$2:$OJ$901,12,MATCH($B$2&"|xK",Aux_puntos!$1:$1,0))="",NA(),INDEX(Aux_puntos!$A$2:$OJ$901,12,MATCH($B$2&"|xK",Aux_puntos!$1:$1,0))),NA()) | AD16: =IFERROR(IF(INDEX(Aux_puntos!$A$2:$OJ$901,12,MATCH($B$2&"|yK",Aux_puntos!$1:$1,0))="",NA(),INDEX(Aux_puntos!$A$2:$OJ$901,12,MATCH($B$2&"|yK",Aux_puntos!$1:$1,0))),NA()) | AE16: =IFERROR(IF(INDEX(Aux_puntos!$A$2:$OJ$901,12,MATCH($B$2&"|xC",Aux_puntos!$1:$1,0))="",NA(),INDEX(Aux_puntos!$A$2:$OJ$901,12,MATCH($B$2&"|xC",Aux_puntos!$1:$1,0))),NA()) | AF16: =IFERROR(IF(INDEX(Aux_puntos!$A$2:$OJ$901,12,MATCH($B$2&"|yC",Aux_puntos!$1:$1,0))="",NA(),INDEX(Aux_puntos!$A$2:$OJ$901,12,MATCH($B$2&"|yC",Aux_puntos!$1:$1,0))),NA()) | AG16: =IFERROR(IF(INDEX(Aux_puntos!$A$2:$OJ$901,12,MATCH($B$2&"|xI",Aux_puntos!$1:$1,0))="",NA(),INDEX(Aux_puntos!$A$2:$OJ$901,12,MATCH($B$2&"|xI",Aux_puntos!$1:$1,0))),NA()) | AH16: =IFERROR(IF(INDEX(Aux_puntos!$A$2:$OJ$901,12,MATCH($B$2&"|yI",Aux_puntos!$1:$1,0))="",NA(),INDEX(Aux_puntos!$A$2:$OJ$901,12,MATCH($B$2&"|yI",Aux_puntos!$1:$1,0))),NA()) | AI16: =IFERROR(IF(INDEX(Aux_puntos!$A$2:$OJ$901,12,MATCH($B$2&"|xN",Aux_puntos!$1:$1,0))="",NA(),INDEX(Aux_puntos!$A$2:$OJ$901,12,MATCH($B$2&"|xN",Aux_puntos!$1:$1,0))),NA()) | AJ16: =IFERROR(IF(INDEX(Aux_puntos!$A$2:$OJ$901,12,MATCH($B$2&"|yN",Aux_puntos!$1:$1,0))="",NA(),INDEX(Aux_puntos!$A$2:$OJ$901,12,MATCH($B$2&"|yN",Aux_puntos!$1:$1,0))),NA())
A17: Efectividad del regenerador, ε_reg [–] | B17: =INDEX(Aux_tablero!$B$30:$AY$30,MATCH($B$2,Aux_tablero!$B$1:$AY$1,0)) | AC17: =IFERROR(IF(INDEX(Aux_puntos!$A$2:$OJ$901,13,MATCH($B$2&"|xK",Aux_puntos!$1:$1,0))="",NA(),INDEX(Aux_puntos!$A$2:$OJ$901,13,MATCH($B$2&"|xK",Aux_puntos!$1:$1,0))),NA()) | AD17: =IFERROR(IF(INDEX(Aux_puntos!$A$2:$OJ$901,13,MATCH($B$2&"|yK",Aux_puntos!$1:$1,0))="",NA(),INDEX(Aux_puntos!$A$2:$OJ$901,13,MATCH($B$2&"|yK",Aux_puntos!$1:$1,0))),NA()) | AE17: =IFERROR(IF(INDEX(Aux_puntos!$A$2:$OJ$901,13,MATCH($B$2&"|xC",Aux_puntos!$1:$1,0))="",NA(),INDEX(Aux_puntos!$A$2:$OJ$901,13,MATCH($B$2&"|xC",Aux_puntos!$1:$1,0))),NA()) | AF17: =IFERROR(IF(INDEX(Aux_puntos!$A$2:$OJ$901,13,MATCH($B$2&"|yC",Aux_puntos!$1:$1,0))="",NA(),INDEX(Aux_puntos!$A$2:$OJ$901,13,MATCH($B$2&"|yC",Aux_puntos!$1:$1,0))),NA()) | AG17: =IFERROR(IF(INDEX(Aux_puntos!$A$2:$OJ$901,13,MATCH($B$2&"|xI",Aux_puntos!$1:$1,0))="",NA(),INDEX(Aux_puntos!$A$2:$OJ$901,13,MATCH($B$2&"|xI",Aux_puntos!$1:$1,0))),NA()) | AH17: =IFERROR(IF(INDEX(Aux_puntos!$A$2:$OJ$901,13,MATCH($B$2&"|yI",Aux_puntos!$1:$1,0))="",NA(),INDEX(Aux_puntos!$A$2:$OJ$901,13,MATCH($B$2&"|yI",Aux_puntos!$1:$1,0))),NA()) | AI17: =IFERROR(IF(INDEX(Aux_puntos!$A$2:$OJ$901,13,MATCH($B$2&"|xN",Aux_puntos!$1:$1,0))="",NA(),INDEX(Aux_puntos!$A$2:$OJ$901,13,MATCH($B$2&"|xN",Aux_puntos!$1:$1,0))),NA()) | AJ17: =IFERROR(IF(INDEX(Aux_puntos!$A$2:$OJ$901,13,MATCH($B$2&"|yN",Aux_puntos!$1:$1,0))="",NA(),INDEX(Aux_puntos!$A$2:$OJ$901,13,MATCH($B$2&"|yN",Aux_puntos!$1:$1,0))),NA())
A18: Efectividad del condensador, ε_cond [–] | B18: =INDEX(Aux_tablero!$B$31:$AY$31,MATCH($B$2,Aux_tablero!$B$1:$AY$1,0)) | AC18: =IFERROR(IF(INDEX(Aux_puntos!$A$2:$OJ$901,14,MATCH($B$2&"|xK",Aux_puntos!$1:$1,0))="",NA(),INDEX(Aux_puntos!$A$2:$OJ$901,14,MATCH($B$2&"|xK",Aux_puntos!$1:$1,0))),NA()) | AD18: =IFERROR(IF(INDEX(Aux_puntos!$A$2:$OJ$901,14,MATCH($B$2&"|yK",Aux_puntos!$1:$1,0))="",NA(),INDEX(Aux_puntos!$A$2:$OJ$901,14,MATCH($B$2&"|yK",Aux_puntos!$1:$1,0))),NA()) | AE18: =IFERROR(IF(INDEX(Aux_puntos!$A$2:$OJ$901,14,MATCH($B$2&"|xC",Aux_puntos!$1:$1,0))="",NA(),INDEX(Aux_puntos!$A$2:$OJ$901,14,MATCH($B$2&"|xC",Aux_puntos!$1:$1,0))),NA()) | AF18: =IFERROR(IF(INDEX(Aux_puntos!$A$2:$OJ$901,14,MATCH($B$2&"|yC",Aux_puntos!$1:$1,0))="",NA(),INDEX(Aux_puntos!$A$2:$OJ$901,14,MATCH($B$2&"|yC",Aux_puntos!$1:$1,0))),NA()) | AG18: =IFERROR(IF(INDEX(Aux_puntos!$A$2:$OJ$901,14,MATCH($B$2&"|xI",Aux_puntos!$1:$1,0))="",NA(),INDEX(Aux_puntos!$A$2:$OJ$901,14,MATCH($B$2&"|xI",Aux_puntos!$1:$1,0))),NA()) | AH18: =IFERROR(IF(INDEX(Aux_puntos!$A$2:$OJ$901,14,MATCH($B$2&"|yI",Aux_puntos!$1:$1,0))="",NA(),INDEX(Aux_puntos!$A$2:$OJ$901,14,MATCH($B$2&"|yI",Aux_puntos!$1:$1,0))),NA()) | AI18: =IFERROR(IF(INDEX(Aux_puntos!$A$2:$OJ$901,14,MATCH($B$2&"|xN",Aux_puntos!$1:$1,0))="",NA(),INDEX(Aux_puntos!$A$2:$OJ$901,14,MATCH($B$2&"|xN",Aux_puntos!$1:$1,0))),NA()) | AJ18: =IFERROR(IF(INDEX(Aux_puntos!$A$2:$OJ$901,14,MATCH($B$2&"|yN",Aux_puntos!$1:$1,0))="",NA(),INDEX(Aux_puntos!$A$2:$OJ$901,14,MATCH($B$2&"|yN",Aux_puntos!$1:$1,0))),NA())
A19: Piso de O2 (T de diseño de la bomba) [K] | B19: =INDEX(Aux_tablero!$B$32:$AY$32,MATCH($B$2,Aux_tablero!$B$1:$AY$1,0)) | AC19: =IFERROR(IF(INDEX(Aux_puntos!$A$2:$OJ$901,15,MATCH($B$2&"|xK",Aux_puntos!$1:$1,0))="",NA(),INDEX(Aux_puntos!$A$2:$OJ$901,15,MATCH($B$2&"|xK",Aux_puntos!$1:$1,0))),NA()) | AD19: =IFERROR(IF(INDEX(Aux_puntos!$A$2:$OJ$901,15,MATCH($B$2&"|yK",Aux_puntos!$1:$1,0))="",NA(),INDEX(Aux_puntos!$A$2:$OJ$901,15,MATCH($B$2&"|yK",Aux_puntos!$1:$1,0))),NA()) | AE19: =IFERROR(IF(INDEX(Aux_puntos!$A$2:$OJ$901,15,MATCH($B$2&"|xC",Aux_puntos!$1:$1,0))="",NA(),INDEX(Aux_puntos!$A$2:$OJ$901,15,MATCH($B$2&"|xC",Aux_puntos!$1:$1,0))),NA()) | AF19: =IFERROR(IF(INDEX(Aux_puntos!$A$2:$OJ$901,15,MATCH($B$2&"|yC",Aux_puntos!$1:$1,0))="",NA(),INDEX(Aux_puntos!$A$2:$OJ$901,15,MATCH($B$2&"|yC",Aux_puntos!$1:$1,0))),NA()) | AG19: =IFERROR(IF(INDEX(Aux_puntos!$A$2:$OJ$901,15,MATCH($B$2&"|xI",Aux_puntos!$1:$1,0))="",NA(),INDEX(Aux_puntos!$A$2:$OJ$901,15,MATCH($B$2&"|xI",Aux_puntos!$1:$1,0))),NA()) | AH19: =IFERROR(IF(INDEX(Aux_puntos!$A$2:$OJ$901,15,MATCH($B$2&"|yI",Aux_puntos!$1:$1,0))="",NA(),INDEX(Aux_puntos!$A$2:$OJ$901,15,MATCH($B$2&"|yI",Aux_puntos!$1:$1,0))),NA()) | AI19: =IFERROR(IF(INDEX(Aux_puntos!$A$2:$OJ$901,15,MATCH($B$2&"|xN",Aux_puntos!$1:$1,0))="",NA(),INDEX(Aux_puntos!$A$2:$OJ$901,15,MATCH($B$2&"|xN",Aux_puntos!$1:$1,0))),NA()) | AJ19: =IFERROR(IF(INDEX(Aux_puntos!$A$2:$OJ$901,15,MATCH($B$2&"|yN",Aux_puntos!$1:$1,0))="",NA(),INDEX(Aux_puntos!$A$2:$OJ$901,15,MATCH($B$2&"|yN",Aux_puntos!$1:$1,0))),NA())
A20: motor | B20: =INDEX(Aux_tablero!$B$33:$AY$33,MATCH($B$2,Aux_tablero!$B$1:$AY$1,0)) | AC20: =IFERROR(IF(INDEX(Aux_puntos!$A$2:$OJ$901,16,MATCH($B$2&"|xK",Aux_puntos!$1:$1,0))="",NA(),INDEX(Aux_puntos!$A$2:$OJ$901,16,MATCH($B$2&"|xK",Aux_puntos!$1:$1,0))),NA()) | AD20: =IFERROR(IF(INDEX(Aux_puntos!$A$2:$OJ$901,16,MATCH($B$2&"|yK",Aux_puntos!$1:$1,0))="",NA(),INDEX(Aux_puntos!$A$2:$OJ$901,16,MATCH($B$2&"|yK",Aux_puntos!$1:$1,0))),NA()) | AE20: =IFERROR(IF(INDEX(Aux_puntos!$A$2:$OJ$901,16,MATCH($B$2&"|xC",Aux_puntos!$1:$1,0))="",NA(),INDEX(Aux_puntos!$A$2:$OJ$901,16,MATCH($B$2&"|xC",Aux_puntos!$1:$1,0))),NA()) | AF20: =IFERROR(IF(INDEX(Aux_puntos!$A$2:$OJ$901,16,MATCH($B$2&"|yC",Aux_puntos!$1:$1,0))="",NA(),INDEX(Aux_puntos!$A$2:$OJ$901,16,MATCH($B$2&"|yC",Aux_puntos!$1:$1,0))),NA()) | AG20: =IFERROR(IF(INDEX(Aux_puntos!$A$2:$OJ$901,16,MATCH($B$2&"|xI",Aux_puntos!$1:$1,0))="",NA(),INDEX(Aux_puntos!$A$2:$OJ$901,16,MATCH($B$2&"|xI",Aux_puntos!$1:$1,0))),NA()) | AH20: =IFERROR(IF(INDEX(Aux_puntos!$A$2:$OJ$901,16,MATCH($B$2&"|yI",Aux_puntos!$1:$1,0))="",NA(),INDEX(Aux_puntos!$A$2:$OJ$901,16,MATCH($B$2&"|yI",Aux_puntos!$1:$1,0))),NA()) | AI20: =IFERROR(IF(INDEX(Aux_puntos!$A$2:$OJ$901,16,MATCH($B$2&"|xN",Aux_puntos!$1:$1,0))="",NA(),INDEX(Aux_puntos!$A$2:$OJ$901,16,MATCH($B$2&"|xN",Aux_puntos!$1:$1,0))),NA()) | AJ20: =IFERROR(IF(INDEX(Aux_puntos!$A$2:$OJ$901,16,MATCH($B$2&"|yN",Aux_puntos!$1:$1,0))="",NA(),INDEX(Aux_puntos!$A$2:$OJ$901,16,MATCH($B$2&"|yN",Aux_puntos!$1:$1,0))),NA())
AC21: =IFERROR(IF(INDEX(Aux_puntos!$A$2:$OJ$901,17,MATCH($B$2&"|xK",Aux_puntos!$1:$1,0))="",NA(),INDEX(Aux_puntos!$A$2:$OJ$901,17,MATCH($B$2&"|xK",Aux_puntos!$1:$1,0))),NA()) | AD21: =IFERROR(IF(INDEX(Aux_puntos!$A$2:$OJ$901,17,MATCH($B$2&"|yK",Aux_puntos!$1:$1,0))="",NA(),INDEX(Aux_puntos!$A$2:$OJ$901,17,MATCH($B$2&"|yK",Aux_puntos!$1:$1,0))),NA()) | AE21: =IFERROR(IF(INDEX(Aux_puntos!$A$2:$OJ$901,17,MATCH($B$2&"|xC",Aux_puntos!$1:$1,0))="",NA(),INDEX(Aux_puntos!$A$2:$OJ$901,17,MATCH($B$2&"|xC",Aux_puntos!$1:$1,0))),NA()) | AF21: =IFERROR(IF(INDEX(Aux_puntos!$A$2:$OJ$901,17,MATCH($B$2&"|yC",Aux_puntos!$1:$1,0))="",NA(),INDEX(Aux_puntos!$A$2:$OJ$901,17,MATCH($B$2&"|yC",Aux_puntos!$1:$1,0))),NA()) | AG21: =IFERROR(IF(INDEX(Aux_puntos!$A$2:$OJ$901,17,MATCH($B$2&"|xI",Aux_puntos!$1:$1,0))="",NA(),INDEX(Aux_puntos!$A$2:$OJ$901,17,MATCH($B$2&"|xI",Aux_puntos!$1:$1,0))),NA()) | AH21: =IFERROR(IF(INDEX(Aux_puntos!$A$2:$OJ$901,17,MATCH($B$2&"|yI",Aux_puntos!$1:$1,0))="",NA(),INDEX(Aux_puntos!$A$2:$OJ$901,17,MATCH($B$2&"|yI",Aux_puntos!$1:$1,0))),NA()) | AI21: =IFERROR(IF(INDEX(Aux_puntos!$A$2:$OJ$901,17,MATCH($B$2&"|xN",Aux_puntos!$1:$1,0))="",NA(),INDEX(Aux_puntos!$A$2:$OJ$901,17,MATCH($B$2&"|xN",Aux_puntos!$1:$1,0))),NA()) | AJ21: =IFERROR(IF(INDEX(Aux_puntos!$A$2:$OJ$901,17,MATCH($B$2&"|yN",Aux_puntos!$1:$1,0))="",NA(),INDEX(Aux_puntos!$A$2:$OJ$901,17,MATCH($B$2&"|yN",Aux_puntos!$1:$1,0))),NA())
A22: Pie: | AC22: =IFERROR(IF(INDEX(Aux_puntos!$A$2:$OJ$901,18,MATCH($B$2&"|xK",Aux_puntos!$1:$1,0))="",NA(),INDEX(Aux_puntos!$A$2:$OJ$901,18,MATCH($B$2&"|xK",Aux_puntos!$1:$1,0))),NA()) | AD22: =IFERROR(IF(INDEX(Aux_puntos!$A$2:$OJ$901,18,MATCH($B$2&"|yK",Aux_puntos!$1:$1,0))="",NA(),INDEX(Aux_puntos!$A$2:$OJ$901,18,MATCH($B$2&"|yK",Aux_puntos!$1:$1,0))),NA()) | AE22: =IFERROR(IF(INDEX(Aux_puntos!$A$2:$OJ$901,18,MATCH($B$2&"|xC",Aux_puntos!$1:$1,0))="",NA(),INDEX(Aux_puntos!$A$2:$OJ$901,18,MATCH($B$2&"|xC",Aux_puntos!$1:$1,0))),NA()) | AF22: =IFERROR(IF(INDEX(Aux_puntos!$A$2:$OJ$901,18,MATCH($B$2&"|yC",Aux_puntos!$1:$1,0))="",NA(),INDEX(Aux_puntos!$A$2:$OJ$901,18,MATCH($B$2&"|yC",Aux_puntos!$1:$1,0))),NA()) | AG22: =IFERROR(IF(INDEX(Aux_puntos!$A$2:$OJ$901,18,MATCH($B$2&"|xI",Aux_puntos!$1:$1,0))="",NA(),INDEX(Aux_puntos!$A$2:$OJ$901,18,MATCH($B$2&"|xI",Aux_puntos!$1:$1,0))),NA()) | AH22: =IFERROR(IF(INDEX(Aux_puntos!$A$2:$OJ$901,18,MATCH($B$2&"|yI",Aux_puntos!$1:$1,0))="",NA(),INDEX(Aux_puntos!$A$2:$OJ$901,18,MATCH($B$2&"|yI",Aux_puntos!$1:$1,0))),NA()) | AI22: =IFERROR(IF(INDEX(Aux_puntos!$A$2:$OJ$901,18,MATCH($B$2&"|xN",Aux_puntos!$1:$1,0))="",NA(),INDEX(Aux_puntos!$A$2:$OJ$901,18,MATCH($B$2&"|xN",Aux_puntos!$1:$1,0))),NA()) | AJ22: =IFERROR(IF(INDEX(Aux_puntos!$A$2:$OJ$901,18,MATCH($B$2&"|yN",Aux_puntos!$1:$1,0))="",NA(),INDEX(Aux_puntos!$A$2:$OJ$901,18,MATCH($B$2&"|yN",Aux_puntos!$1:$1,0))),NA())
A23: =INDEX(Aux_tablero!$B$10:$AY$10,MATCH($B$2,Aux_tablero!$B$1:$AY$1,0)) | AC23: =IFERROR(IF(INDEX(Aux_puntos!$A$2:$OJ$901,19,MATCH($B$2&"|xK",Aux_puntos!$1:$1,0))="",NA(),INDEX(Aux_puntos!$A$2:$OJ$901,19,MATCH($B$2&"|xK",Aux_puntos!$1:$1,0))),NA()) | AD23: =IFERROR(IF(INDEX(Aux_puntos!$A$2:$OJ$901,19,MATCH($B$2&"|yK",Aux_puntos!$1:$1,0))="",NA(),INDEX(Aux_puntos!$A$2:$OJ$901,19,MATCH($B$2&"|yK",Aux_puntos!$1:$1,0))),NA()) | AE23: =IFERROR(IF(INDEX(Aux_puntos!$A$2:$OJ$901,19,MATCH($B$2&"|xC",Aux_puntos!$1:$1,0))="",NA(),INDEX(Aux_puntos!$A$2:$OJ$901,19,MATCH($B$2&"|xC",Aux_puntos!$1:$1,0))),NA()) | AF23: =IFERROR(IF(INDEX(Aux_puntos!$A$2:$OJ$901,19,MATCH($B$2&"|yC",Aux_puntos!$1:$1,0))="",NA(),INDEX(Aux_puntos!$A$2:$OJ$901,19,MATCH($B$2&"|yC",Aux_puntos!$1:$1,0))),NA()) | AG23: =IFERROR(IF(INDEX(Aux_puntos!$A$2:$OJ$901,19,MATCH($B$2&"|xI",Aux_puntos!$1:$1,0))="",NA(),INDEX(Aux_puntos!$A$2:$OJ$901,19,MATCH($B$2&"|xI",Aux_puntos!$1:$1,0))),NA()) | AH23: =IFERROR(IF(INDEX(Aux_puntos!$A$2:$OJ$901,19,MATCH($B$2&"|yI",Aux_puntos!$1:$1,0))="",NA(),INDEX(Aux_puntos!$A$2:$OJ$901,19,MATCH($B$2&"|yI",Aux_puntos!$1:$1,0))),NA()) | AI23: =IFERROR(IF(INDEX(Aux_puntos!$A$2:$OJ$901,19,MATCH($B$2&"|xN",Aux_puntos!$1:$1,0))="",NA(),INDEX(Aux_puntos!$A$2:$OJ$901,19,MATCH($B$2&"|xN",Aux_puntos!$1:$1,0))),NA()) | AJ23: =IFERROR(IF(INDEX(Aux_puntos!$A$2:$OJ$901,19,MATCH($B$2&"|yN",Aux_puntos!$1:$1,0))="",NA(),INDEX(Aux_puntos!$A$2:$OJ$901,19,MATCH($B$2&"|yN",Aux_puntos!$1:$1,0))),NA())
AC24: =IFERROR(IF(INDEX(Aux_puntos!$A$2:$OJ$901,20,MATCH($B$2&"|xK",Aux_puntos!$1:$1,0))="",NA(),INDEX(Aux_puntos!$A$2:$OJ$901,20,MATCH($B$2&"|xK",Aux_puntos!$1:$1,0))),NA()) | AD24: =IFERROR(IF(INDEX(Aux_puntos!$A$2:$OJ$901,20,MATCH($B$2&"|yK",Aux_puntos!$1:$1,0))="",NA(),INDEX(Aux_puntos!$A$2:$OJ$901,20,MATCH($B$2&"|yK",Aux_puntos!$1:$1,0))),NA()) | AE24: =IFERROR(IF(INDEX(Aux_puntos!$A$2:$OJ$901,20,MATCH($B$2&"|xC",Aux_puntos!$1:$1,0))="",NA(),INDEX(Aux_puntos!$A$2:$OJ$901,20,MATCH($B$2&"|xC",Aux_puntos!$1:$1,0))),NA()) | AF24: =IFERROR(IF(INDEX(Aux_puntos!$A$2:$OJ$901,20,MATCH($B$2&"|yC",Aux_puntos!$1:$1,0))="",NA(),INDEX(Aux_puntos!$A$2:$OJ$901,20,MATCH($B$2&"|yC",Aux_puntos!$1:$1,0))),NA()) | AG24: =IFERROR(IF(INDEX(Aux_puntos!$A$2:$OJ$901,20,MATCH($B$2&"|xI",Aux_puntos!$1:$1,0))="",NA(),INDEX(Aux_puntos!$A$2:$OJ$901,20,MATCH($B$2&"|xI",Aux_puntos!$1:$1,0))),NA()) | AH24: =IFERROR(IF(INDEX(Aux_puntos!$A$2:$OJ$901,20,MATCH($B$2&"|yI",Aux_puntos!$1:$1,0))="",NA(),INDEX(Aux_puntos!$A$2:$OJ$901,20,MATCH($B$2&"|yI",Aux_puntos!$1:$1,0))),NA()) | AI24: =IFERROR(IF(INDEX(Aux_puntos!$A$2:$OJ$901,20,MATCH($B$2&"|xN",Aux_puntos!$1:$1,0))="",NA(),INDEX(Aux_puntos!$A$2:$OJ$901,20,MATCH($B$2&"|xN",Aux_puntos!$1:$1,0))),NA()) | AJ24: =IFERROR(IF(INDEX(Aux_puntos!$A$2:$OJ$901,20,MATCH($B$2&"|yN",Aux_puntos!$1:$1,0))="",NA(),INDEX(Aux_puntos!$A$2:$OJ$901,20,MATCH($B$2&"|yN",Aux_puntos!$1:$1,0))),NA())
AC25: =IFERROR(IF(INDEX(Aux_puntos!$A$2:$OJ$901,21,MATCH($B$2&"|xK",Aux_puntos!$1:$1,0))="",NA(),INDEX(Aux_puntos!$A$2:$OJ$901,21,MATCH($B$2&"|xK",Aux_puntos!$1:$1,0))),NA()) | AD25: =IFERROR(IF(INDEX(Aux_puntos!$A$2:$OJ$901,21,MATCH($B$2&"|yK",Aux_puntos!$1:$1,0))="",NA(),INDEX(Aux_puntos!$A$2:$OJ$901,21,MATCH($B$2&"|yK",Aux_puntos!$1:$1,0))),NA()) | AE25: =IFERROR(IF(INDEX(Aux_puntos!$A$2:$OJ$901,21,MATCH($B$2&"|xC",Aux_puntos!$1:$1,0))="",NA(),INDEX(Aux_puntos!$A$2:$OJ$901,21,MATCH($B$2&"|xC",Aux_puntos!$1:$1,0))),NA()) | AF25: =IFERROR(IF(INDEX(Aux_puntos!$A$2:$OJ$901,21,MATCH($B$2&"|yC",Aux_puntos!$1:$1,0))="",NA(),INDEX(Aux_puntos!$A$2:$OJ$901,21,MATCH($B$2&"|yC",Aux_puntos!$1:$1,0))),NA()) | AG25: =IFERROR(IF(INDEX(Aux_puntos!$A$2:$OJ$901,21,MATCH($B$2&"|xI",Aux_puntos!$1:$1,0))="",NA(),INDEX(Aux_puntos!$A$2:$OJ$901,21,MATCH($B$2&"|xI",Aux_puntos!$1:$1,0))),NA()) | AH25: =IFERROR(IF(INDEX(Aux_puntos!$A$2:$OJ$901,21,MATCH($B$2&"|yI",Aux_puntos!$1:$1,0))="",NA(),INDEX(Aux_puntos!$A$2:$OJ$901,21,MATCH($B$2&"|yI",Aux_puntos!$1:$1,0))),NA()) | AI25: =IFERROR(IF(INDEX(Aux_puntos!$A$2:$OJ$901,21,MATCH($B$2&"|xN",Aux_puntos!$1:$1,0))="",NA(),INDEX(Aux_puntos!$A$2:$OJ$901,21,MATCH($B$2&"|xN",Aux_puntos!$1:$1,0))),NA()) | AJ25: =IFERROR(IF(INDEX(Aux_puntos!$A$2:$OJ$901,21,MATCH($B$2&"|yN",Aux_puntos!$1:$1,0))="",NA(),INDEX(Aux_puntos!$A$2:$OJ$901,21,MATCH($B$2&"|yN",Aux_puntos!$1:$1,0))),NA())
AC26: =IFERROR(IF(INDEX(Aux_puntos!$A$2:$OJ$901,22,MATCH($B$2&"|xK",Aux_puntos!$1:$1,0))="",NA(),INDEX(Aux_puntos!$A$2:$OJ$901,22,MATCH($B$2&"|xK",Aux_puntos!$1:$1,0))),NA()) | AD26: =IFERROR(IF(INDEX(Aux_puntos!$A$2:$OJ$901,22,MATCH($B$2&"|yK",Aux_puntos!$1:$1,0))="",NA(),INDEX(Aux_puntos!$A$2:$OJ$901,22,MATCH($B$2&"|yK",Aux_puntos!$1:$1,0))),NA()) | AE26: =IFERROR(IF(INDEX(Aux_puntos!$A$2:$OJ$901,22,MATCH($B$2&"|xC",Aux_puntos!$1:$1,0))="",NA(),INDEX(Aux_puntos!$A$2:$OJ$901,22,MATCH($B$2&"|xC",Aux_puntos!$1:$1,0))),NA()) | AF26: =IFERROR(IF(INDEX(Aux_puntos!$A$2:$OJ$901,22,MATCH($B$2&"|yC",Aux_puntos!$1:$1,0))="",NA(),INDEX(Aux_puntos!$A$2:$OJ$901,22,MATCH($B$2&"|yC",Aux_puntos!$1:$1,0))),NA()) | AG26: =IFERROR(IF(INDEX(Aux_puntos!$A$2:$OJ$901,22,MATCH($B$2&"|xI",Aux_puntos!$1:$1,0))="",NA(),INDEX(Aux_puntos!$A$2:$OJ$901,22,MATCH($B$2&"|xI",Aux_puntos!$1:$1,0))),NA()) | AH26: =IFERROR(IF(INDEX(Aux_puntos!$A$2:$OJ$901,22,MATCH($B$2&"|yI",Aux_puntos!$1:$1,0))="",NA(),INDEX(Aux_puntos!$A$2:$OJ$901,22,MATCH($B$2&"|yI",Aux_puntos!$1:$1,0))),NA()) | AI26: =IFERROR(IF(INDEX(Aux_puntos!$A$2:$OJ$901,22,MATCH($B$2&"|xN",Aux_puntos!$1:$1,0))="",NA(),INDEX(Aux_puntos!$A$2:$OJ$901,22,MATCH($B$2&"|xN",Aux_puntos!$1:$1,0))),NA()) | AJ26: =IFERROR(IF(INDEX(Aux_puntos!$A$2:$OJ$901,22,MATCH($B$2&"|yN",Aux_puntos!$1:$1,0))="",NA(),INDEX(Aux_puntos!$A$2:$OJ$901,22,MATCH($B$2&"|yN",Aux_puntos!$1:$1,0))),NA())
AC27: =IFERROR(IF(INDEX(Aux_puntos!$A$2:$OJ$901,23,MATCH($B$2&"|xK",Aux_puntos!$1:$1,0))="",NA(),INDEX(Aux_puntos!$A$2:$OJ$901,23,MATCH($B$2&"|xK",Aux_puntos!$1:$1,0))),NA()) | AD27: =IFERROR(IF(INDEX(Aux_puntos!$A$2:$OJ$901,23,MATCH($B$2&"|yK",Aux_puntos!$1:$1,0))="",NA(),INDEX(Aux_puntos!$A$2:$OJ$901,23,MATCH($B$2&"|yK",Aux_puntos!$1:$1,0))),NA()) | AE27: =IFERROR(IF(INDEX(Aux_puntos!$A$2:$OJ$901,23,MATCH($B$2&"|xC",Aux_puntos!$1:$1,0))="",NA(),INDEX(Aux_puntos!$A$2:$OJ$901,23,MATCH($B$2&"|xC",Aux_puntos!$1:$1,0))),NA()) | AF27: =IFERROR(IF(INDEX(Aux_puntos!$A$2:$OJ$901,23,MATCH($B$2&"|yC",Aux_puntos!$1:$1,0))="",NA(),INDEX(Aux_puntos!$A$2:$OJ$901,23,MATCH($B$2&"|yC",Aux_puntos!$1:$1,0))),NA()) | AG27: =IFERROR(IF(INDEX(Aux_puntos!$A$2:$OJ$901,23,MATCH($B$2&"|xI",Aux_puntos!$1:$1,0))="",NA(),INDEX(Aux_puntos!$A$2:$OJ$901,23,MATCH($B$2&"|xI",Aux_puntos!$1:$1,0))),NA()) | AH27: =IFERROR(IF(INDEX(Aux_puntos!$A$2:$OJ$901,23,MATCH($B$2&"|yI",Aux_puntos!$1:$1,0))="",NA(),INDEX(Aux_puntos!$A$2:$OJ$901,23,MATCH($B$2&"|yI",Aux_puntos!$1:$1,0))),NA()) | AI27: =IFERROR(IF(INDEX(Aux_puntos!$A$2:$OJ$901,23,MATCH($B$2&"|xN",Aux_puntos!$1:$1,0))="",NA(),INDEX(Aux_puntos!$A$2:$OJ$901,23,MATCH($B$2&"|xN",Aux_puntos!$1:$1,0))),NA()) | AJ27: =IFERROR(IF(INDEX(Aux_puntos!$A$2:$OJ$901,23,MATCH($B$2&"|yN",Aux_puntos!$1:$1,0))="",NA(),INDEX(Aux_puntos!$A$2:$OJ$901,23,MATCH($B$2&"|yN",Aux_puntos!$1:$1,0))),NA())
AC28: =IFERROR(IF(INDEX(Aux_puntos!$A$2:$OJ$901,24,MATCH($B$2&"|xK",Aux_puntos!$1:$1,0))="",NA(),INDEX(Aux_puntos!$A$2:$OJ$901,24,MATCH($B$2&"|xK",Aux_puntos!$1:$1,0))),NA()) | AD28: =IFERROR(IF(INDEX(Aux_puntos!$A$2:$OJ$901,24,MATCH($B$2&"|yK",Aux_puntos!$1:$1,0))="",NA(),INDEX(Aux_puntos!$A$2:$OJ$901,24,MATCH($B$2&"|yK",Aux_puntos!$1:$1,0))),NA()) | AE28: =IFERROR(IF(INDEX(Aux_puntos!$A$2:$OJ$901,24,MATCH($B$2&"|xC",Aux_puntos!$1:$1,0))="",NA(),INDEX(Aux_puntos!$A$2:$OJ$901,24,MATCH($B$2&"|xC",Aux_puntos!$1:$1,0))),NA()) | AF28: =IFERROR(IF(INDEX(Aux_puntos!$A$2:$OJ$901,24,MATCH($B$2&"|yC",Aux_puntos!$1:$1,0))="",NA(),INDEX(Aux_puntos!$A$2:$OJ$901,24,MATCH($B$2&"|yC",Aux_puntos!$1:$1,0))),NA()) | AG28: =IFERROR(IF(INDEX(Aux_puntos!$A$2:$OJ$901,24,MATCH($B$2&"|xI",Aux_puntos!$1:$1,0))="",NA(),INDEX(Aux_puntos!$A$2:$OJ$901,24,MATCH($B$2&"|xI",Aux_puntos!$1:$1,0))),NA()) | AH28: =IFERROR(IF(INDEX(Aux_puntos!$A$2:$OJ$901,24,MATCH($B$2&"|yI",Aux_puntos!$1:$1,0))="",NA(),INDEX(Aux_puntos!$A$2:$OJ$901,24,MATCH($B$2&"|yI",Aux_puntos!$1:$1,0))),NA()) | AI28: =IFERROR(IF(INDEX(Aux_puntos!$A$2:$OJ$901,24,MATCH($B$2&"|xN",Aux_puntos!$1:$1,0))="",NA(),INDEX(Aux_puntos!$A$2:$OJ$901,24,MATCH($B$2&"|xN",Aux_puntos!$1:$1,0))),NA()) | AJ28: =IFERROR(IF(INDEX(Aux_puntos!$A$2:$OJ$901,24,MATCH($B$2&"|yN",Aux_puntos!$1:$1,0))="",NA(),INDEX(Aux_puntos!$A$2:$OJ$901,24,MATCH($B$2&"|yN",Aux_puntos!$1:$1,0))),NA())
AC29: =IFERROR(IF(INDEX(Aux_puntos!$A$2:$OJ$901,25,MATCH($B$2&"|xK",Aux_puntos!$1:$1,0))="",NA(),INDEX(Aux_puntos!$A$2:$OJ$901,25,MATCH($B$2&"|xK",Aux_puntos!$1:$1,0))),NA()) | AD29: =IFERROR(IF(INDEX(Aux_puntos!$A$2:$OJ$901,25,MATCH($B$2&"|yK",Aux_puntos!$1:$1,0))="",NA(),INDEX(Aux_puntos!$A$2:$OJ$901,25,MATCH($B$2&"|yK",Aux_puntos!$1:$1,0))),NA()) | AE29: =IFERROR(IF(INDEX(Aux_puntos!$A$2:$OJ$901,25,MATCH($B$2&"|xC",Aux_puntos!$1:$1,0))="",NA(),INDEX(Aux_puntos!$A$2:$OJ$901,25,MATCH($B$2&"|xC",Aux_puntos!$1:$1,0))),NA()) | AF29: =IFERROR(IF(INDEX(Aux_puntos!$A$2:$OJ$901,25,MATCH($B$2&"|yC",Aux_puntos!$1:$1,0))="",NA(),INDEX(Aux_puntos!$A$2:$OJ$901,25,MATCH($B$2&"|yC",Aux_puntos!$1:$1,0))),NA()) | AG29: =IFERROR(IF(INDEX(Aux_puntos!$A$2:$OJ$901,25,MATCH($B$2&"|xI",Aux_puntos!$1:$1,0))="",NA(),INDEX(Aux_puntos!$A$2:$OJ$901,25,MATCH($B$2&"|xI",Aux_puntos!$1:$1,0))),NA()) | AH29: =IFERROR(IF(INDEX(Aux_puntos!$A$2:$OJ$901,25,MATCH($B$2&"|yI",Aux_puntos!$1:$1,0))="",NA(),INDEX(Aux_puntos!$A$2:$OJ$901,25,MATCH($B$2&"|yI",Aux_puntos!$1:$1,0))),NA()) | AI29: =IFERROR(IF(INDEX(Aux_puntos!$A$2:$OJ$901,25,MATCH($B$2&"|xN",Aux_puntos!$1:$1,0))="",NA(),INDEX(Aux_puntos!$A$2:$OJ$901,25,MATCH($B$2&"|xN",Aux_puntos!$1:$1,0))),NA()) | AJ29: =IFERROR(IF(INDEX(Aux_puntos!$A$2:$OJ$901,25,MATCH($B$2&"|yN",Aux_puntos!$1:$1,0))="",NA(),INDEX(Aux_puntos!$A$2:$OJ$901,25,MATCH($B$2&"|yN",Aux_puntos!$1:$1,0))),NA())
AC30: =IFERROR(IF(INDEX(Aux_puntos!$A$2:$OJ$901,26,MATCH($B$2&"|xK",Aux_puntos!$1:$1,0))="",NA(),INDEX(Aux_puntos!$A$2:$OJ$901,26,MATCH($B$2&"|xK",Aux_puntos!$1:$1,0))),NA()) | AD30: =IFERROR(IF(INDEX(Aux_puntos!$A$2:$OJ$901,26,MATCH($B$2&"|yK",Aux_puntos!$1:$1,0))="",NA(),INDEX(Aux_puntos!$A$2:$OJ$901,26,MATCH($B$2&"|yK",Aux_puntos!$1:$1,0))),NA()) | AE30: =IFERROR(IF(INDEX(Aux_puntos!$A$2:$OJ$901,26,MATCH($B$2&"|xC",Aux_puntos!$1:$1,0))="",NA(),INDEX(Aux_puntos!$A$2:$OJ$901,26,MATCH($B$2&"|xC",Aux_puntos!$1:$1,0))),NA()) | AF30: =IFERROR(IF(INDEX(Aux_puntos!$A$2:$OJ$901,26,MATCH($B$2&"|yC",Aux_puntos!$1:$1,0))="",NA(),INDEX(Aux_puntos!$A$2:$OJ$901,26,MATCH($B$2&"|yC",Aux_puntos!$1:$1,0))),NA()) | AG30: =IFERROR(IF(INDEX(Aux_puntos!$A$2:$OJ$901,26,MATCH($B$2&"|xI",Aux_puntos!$1:$1,0))="",NA(),INDEX(Aux_puntos!$A$2:$OJ$901,26,MATCH($B$2&"|xI",Aux_puntos!$1:$1,0))),NA()) | AH30: =IFERROR(IF(INDEX(Aux_puntos!$A$2:$OJ$901,26,MATCH($B$2&"|yI",Aux_puntos!$1:$1,0))="",NA(),INDEX(Aux_puntos!$A$2:$OJ$901,26,MATCH($B$2&"|yI",Aux_puntos!$1:$1,0))),NA()) | AI30: =IFERROR(IF(INDEX(Aux_puntos!$A$2:$OJ$901,26,MATCH($B$2&"|xN",Aux_puntos!$1:$1,0))="",NA(),INDEX(Aux_puntos!$A$2:$OJ$901,26,MATCH($B$2&"|xN",Aux_puntos!$1:$1,0))),NA()) | AJ30: =IFERROR(IF(INDEX(Aux_puntos!$A$2:$OJ$901,26,MATCH($B$2&"|yN",Aux_puntos!$1:$1,0))="",NA(),INDEX(Aux_puntos!$A$2:$OJ$901,26,MATCH($B$2&"|yN",Aux_puntos!$1:$1,0))),NA())
AC31: =IFERROR(IF(INDEX(Aux_puntos!$A$2:$OJ$901,27,MATCH($B$2&"|xK",Aux_puntos!$1:$1,0))="",NA(),INDEX(Aux_puntos!$A$2:$OJ$901,27,MATCH($B$2&"|xK",Aux_puntos!$1:$1,0))),NA()) | AD31: =IFERROR(IF(INDEX(Aux_puntos!$A$2:$OJ$901,27,MATCH($B$2&"|yK",Aux_puntos!$1:$1,0))="",NA(),INDEX(Aux_puntos!$A$2:$OJ$901,27,MATCH($B$2&"|yK",Aux_puntos!$1:$1,0))),NA()) | AE31: =IFERROR(IF(INDEX(Aux_puntos!$A$2:$OJ$901,27,MATCH($B$2&"|xC",Aux_puntos!$1:$1,0))="",NA(),INDEX(Aux_puntos!$A$2:$OJ$901,27,MATCH($B$2&"|xC",Aux_puntos!$1:$1,0))),NA()) | AF31: =IFERROR(IF(INDEX(Aux_puntos!$A$2:$OJ$901,27,MATCH($B$2&"|yC",Aux_puntos!$1:$1,0))="",NA(),INDEX(Aux_puntos!$A$2:$OJ$901,27,MATCH($B$2&"|yC",Aux_puntos!$1:$1,0))),NA()) | AG31: =IFERROR(IF(INDEX(Aux_puntos!$A$2:$OJ$901,27,MATCH($B$2&"|xI",Aux_puntos!$1:$1,0))="",NA(),INDEX(Aux_puntos!$A$2:$OJ$901,27,MATCH($B$2&"|xI",Aux_puntos!$1:$1,0))),NA()) | AH31: =IFERROR(IF(INDEX(Aux_puntos!$A$2:$OJ$901,27,MATCH($B$2&"|yI",Aux_puntos!$1:$1,0))="",NA(),INDEX(Aux_puntos!$A$2:$OJ$901,27,MATCH($B$2&"|yI",Aux_puntos!$1:$1,0))),NA()) | AI31: =IFERROR(IF(INDEX(Aux_puntos!$A$2:$OJ$901,27,MATCH($B$2&"|xN",Aux_puntos!$1:$1,0))="",NA(),INDEX(Aux_puntos!$A$2:$OJ$901,27,MATCH($B$2&"|xN",Aux_puntos!$1:$1,0))),NA()) | AJ31: =IFERROR(IF(INDEX(Aux_puntos!$A$2:$OJ$901,27,MATCH($B$2&"|yN",Aux_puntos!$1:$1,0))="",NA(),INDEX(Aux_puntos!$A$2:$OJ$901,27,MATCH($B$2&"|yN",Aux_puntos!$1:$1,0))),NA())
AC32: =IFERROR(IF(INDEX(Aux_puntos!$A$2:$OJ$901,28,MATCH($B$2&"|xK",Aux_puntos!$1:$1,0))="",NA(),INDEX(Aux_puntos!$A$2:$OJ$901,28,MATCH($B$2&"|xK",Aux_puntos!$1:$1,0))),NA()) | AD32: =IFERROR(IF(INDEX(Aux_puntos!$A$2:$OJ$901,28,MATCH($B$2&"|yK",Aux_puntos!$1:$1,0))="",NA(),INDEX(Aux_puntos!$A$2:$OJ$901,28,MATCH($B$2&"|yK",Aux_puntos!$1:$1,0))),NA()) | AE32: =IFERROR(IF(INDEX(Aux_puntos!$A$2:$OJ$901,28,MATCH($B$2&"|xC",Aux_puntos!$1:$1,0))="",NA(),INDEX(Aux_puntos!$A$2:$OJ$901,28,MATCH($B$2&"|xC",Aux_puntos!$1:$1,0))),NA()) | AF32: =IFERROR(IF(INDEX(Aux_puntos!$A$2:$OJ$901,28,MATCH($B$2&"|yC",Aux_puntos!$1:$1,0))="",NA(),INDEX(Aux_puntos!$A$2:$OJ$901,28,MATCH($B$2&"|yC",Aux_puntos!$1:$1,0))),NA()) | AG32: =IFERROR(IF(INDEX(Aux_puntos!$A$2:$OJ$901,28,MATCH($B$2&"|xI",Aux_puntos!$1:$1,0))="",NA(),INDEX(Aux_puntos!$A$2:$OJ$901,28,MATCH($B$2&"|xI",Aux_puntos!$1:$1,0))),NA()) | AH32: =IFERROR(IF(INDEX(Aux_puntos!$A$2:$OJ$901,28,MATCH($B$2&"|yI",Aux_puntos!$1:$1,0))="",NA(),INDEX(Aux_puntos!$A$2:$OJ$901,28,MATCH($B$2&"|yI",Aux_puntos!$1:$1,0))),NA()) | AI32: =IFERROR(IF(INDEX(Aux_puntos!$A$2:$OJ$901,28,MATCH($B$2&"|xN",Aux_puntos!$1:$1,0))="",NA(),INDEX(Aux_puntos!$A$2:$OJ$901,28,MATCH($B$2&"|xN",Aux_puntos!$1:$1,0))),NA()) | AJ32: =IFERROR(IF(INDEX(Aux_puntos!$A$2:$OJ$901,28,MATCH($B$2&"|yN",Aux_puntos!$1:$1,0))="",NA(),INDEX(Aux_puntos!$A$2:$OJ$901,28,MATCH($B$2&"|yN",Aux_puntos!$1:$1,0))),NA())
AC33: =IFERROR(IF(INDEX(Aux_puntos!$A$2:$OJ$901,29,MATCH($B$2&"|xK",Aux_puntos!$1:$1,0))="",NA(),INDEX(Aux_puntos!$A$2:$OJ$901,29,MATCH($B$2&"|xK",Aux_puntos!$1:$1,0))),NA()) | AD33: =IFERROR(IF(INDEX(Aux_puntos!$A$2:$OJ$901,29,MATCH($B$2&"|yK",Aux_puntos!$1:$1,0))="",NA(),INDEX(Aux_puntos!$A$2:$OJ$901,29,MATCH($B$2&"|yK",Aux_puntos!$1:$1,0))),NA()) | AE33: =IFERROR(IF(INDEX(Aux_puntos!$A$2:$OJ$901,29,MATCH($B$2&"|xC",Aux_puntos!$1:$1,0))="",NA(),INDEX(Aux_puntos!$A$2:$OJ$901,29,MATCH($B$2&"|xC",Aux_puntos!$1:$1,0))),NA()) | AF33: =IFERROR(IF(INDEX(Aux_puntos!$A$2:$OJ$901,29,MATCH($B$2&"|yC",Aux_puntos!$1:$1,0))="",NA(),INDEX(Aux_puntos!$A$2:$OJ$901,29,MATCH($B$2&"|yC",Aux_puntos!$1:$1,0))),NA()) | AG33: =IFERROR(IF(INDEX(Aux_puntos!$A$2:$OJ$901,29,MATCH($B$2&"|xI",Aux_puntos!$1:$1,0))="",NA(),INDEX(Aux_puntos!$A$2:$OJ$901,29,MATCH($B$2&"|xI",Aux_puntos!$1:$1,0))),NA()) | AH33: =IFERROR(IF(INDEX(Aux_puntos!$A$2:$OJ$901,29,MATCH($B$2&"|yI",Aux_puntos!$1:$1,0))="",NA(),INDEX(Aux_puntos!$A$2:$OJ$901,29,MATCH($B$2&"|yI",Aux_puntos!$1:$1,0))),NA()) | AI33: =IFERROR(IF(INDEX(Aux_puntos!$A$2:$OJ$901,29,MATCH($B$2&"|xN",Aux_puntos!$1:$1,0))="",NA(),INDEX(Aux_puntos!$A$2:$OJ$901,29,MATCH($B$2&"|xN",Aux_puntos!$1:$1,0))),NA()) | AJ33: =IFERROR(IF(INDEX(Aux_puntos!$A$2:$OJ$901,29,MATCH($B$2&"|yN",Aux_puntos!$1:$1,0))="",NA(),INDEX(Aux_puntos!$A$2:$OJ$901,29,MATCH($B$2&"|yN",Aux_puntos!$1:$1,0))),NA())
AC34: =IFERROR(IF(INDEX(Aux_puntos!$A$2:$OJ$901,30,MATCH($B$2&"|xK",Aux_puntos!$1:$1,0))="",NA(),INDEX(Aux_puntos!$A$2:$OJ$901,30,MATCH($B$2&"|xK",Aux_puntos!$1:$1,0))),NA()) | AD34: =IFERROR(IF(INDEX(Aux_puntos!$A$2:$OJ$901,30,MATCH($B$2&"|yK",Aux_puntos!$1:$1,0))="",NA(),INDEX(Aux_puntos!$A$2:$OJ$901,30,MATCH($B$2&"|yK",Aux_puntos!$1:$1,0))),NA()) | AE34: =IFERROR(IF(INDEX(Aux_puntos!$A$2:$OJ$901,30,MATCH($B$2&"|xC",Aux_puntos!$1:$1,0))="",NA(),INDEX(Aux_puntos!$A$2:$OJ$901,30,MATCH($B$2&"|xC",Aux_puntos!$1:$1,0))),NA()) | AF34: =IFERROR(IF(INDEX(Aux_puntos!$A$2:$OJ$901,30,MATCH($B$2&"|yC",Aux_puntos!$1:$1,0))="",NA(),INDEX(Aux_puntos!$A$2:$OJ$901,30,MATCH($B$2&"|yC",Aux_puntos!$1:$1,0))),NA()) | AG34: =IFERROR(IF(INDEX(Aux_puntos!$A$2:$OJ$901,30,MATCH($B$2&"|xI",Aux_puntos!$1:$1,0))="",NA(),INDEX(Aux_puntos!$A$2:$OJ$901,30,MATCH($B$2&"|xI",Aux_puntos!$1:$1,0))),NA()) | AH34: =IFERROR(IF(INDEX(Aux_puntos!$A$2:$OJ$901,30,MATCH($B$2&"|yI",Aux_puntos!$1:$1,0))="",NA(),INDEX(Aux_puntos!$A$2:$OJ$901,30,MATCH($B$2&"|yI",Aux_puntos!$1:$1,0))),NA()) | AI34: =IFERROR(IF(INDEX(Aux_puntos!$A$2:$OJ$901,30,MATCH($B$2&"|xN",Aux_puntos!$1:$1,0))="",NA(),INDEX(Aux_puntos!$A$2:$OJ$901,30,MATCH($B$2&"|xN",Aux_puntos!$1:$1,0))),NA()) | AJ34: =IFERROR(IF(INDEX(Aux_puntos!$A$2:$OJ$901,30,MATCH($B$2&"|yN",Aux_puntos!$1:$1,0))="",NA(),INDEX(Aux_puntos!$A$2:$OJ$901,30,MATCH($B$2&"|yN",Aux_puntos!$1:$1,0))),NA())
AC35: =IFERROR(IF(INDEX(Aux_puntos!$A$2:$OJ$901,31,MATCH($B$2&"|xK",Aux_puntos!$1:$1,0))="",NA(),INDEX(Aux_puntos!$A$2:$OJ$901,31,MATCH($B$2&"|xK",Aux_puntos!$1:$1,0))),NA()) | AD35: =IFERROR(IF(INDEX(Aux_puntos!$A$2:$OJ$901,31,MATCH($B$2&"|yK",Aux_puntos!$1:$1,0))="",NA(),INDEX(Aux_puntos!$A$2:$OJ$901,31,MATCH($B$2&"|yK",Aux_puntos!$1:$1,0))),NA()) | AE35: =IFERROR(IF(INDEX(Aux_puntos!$A$2:$OJ$901,31,MATCH($B$2&"|xC",Aux_puntos!$1:$1,0))="",NA(),INDEX(Aux_puntos!$A$2:$OJ$901,31,MATCH($B$2&"|xC",Aux_puntos!$1:$1,0))),NA()) | AF35: =IFERROR(IF(INDEX(Aux_puntos!$A$2:$OJ$901,31,MATCH($B$2&"|yC",Aux_puntos!$1:$1,0))="",NA(),INDEX(Aux_puntos!$A$2:$OJ$901,31,MATCH($B$2&"|yC",Aux_puntos!$1:$1,0))),NA()) | AG35: =IFERROR(IF(INDEX(Aux_puntos!$A$2:$OJ$901,31,MATCH($B$2&"|xI",Aux_puntos!$1:$1,0))="",NA(),INDEX(Aux_puntos!$A$2:$OJ$901,31,MATCH($B$2&"|xI",Aux_puntos!$1:$1,0))),NA()) | AH35: =IFERROR(IF(INDEX(Aux_puntos!$A$2:$OJ$901,31,MATCH($B$2&"|yI",Aux_puntos!$1:$1,0))="",NA(),INDEX(Aux_puntos!$A$2:$OJ$901,31,MATCH($B$2&"|yI",Aux_puntos!$1:$1,0))),NA()) | AI35: =IFERROR(IF(INDEX(Aux_puntos!$A$2:$OJ$901,31,MATCH($B$2&"|xN",Aux_puntos!$1:$1,0))="",NA(),INDEX(Aux_puntos!$A$2:$OJ$901,31,MATCH($B$2&"|xN",Aux_puntos!$1:$1,0))),NA()) | AJ35: =IFERROR(IF(INDEX(Aux_puntos!$A$2:$OJ$901,31,MATCH($B$2&"|yN",Aux_puntos!$1:$1,0))="",NA(),INDEX(Aux_puntos!$A$2:$OJ$901,31,MATCH($B$2&"|yN",Aux_puntos!$1:$1,0))),NA())
AC36: =IFERROR(IF(INDEX(Aux_puntos!$A$2:$OJ$901,32,MATCH($B$2&"|xK",Aux_puntos!$1:$1,0))="",NA(),INDEX(Aux_puntos!$A$2:$OJ$901,32,MATCH($B$2&"|xK",Aux_puntos!$1:$1,0))),NA()) | AD36: =IFERROR(IF(INDEX(Aux_puntos!$A$2:$OJ$901,32,MATCH($B$2&"|yK",Aux_puntos!$1:$1,0))="",NA(),INDEX(Aux_puntos!$A$2:$OJ$901,32,MATCH($B$2&"|yK",Aux_puntos!$1:$1,0))),NA()) | AE36: =IFERROR(IF(INDEX(Aux_puntos!$A$2:$OJ$901,32,MATCH($B$2&"|xC",Aux_puntos!$1:$1,0))="",NA(),INDEX(Aux_puntos!$A$2:$OJ$901,32,MATCH($B$2&"|xC",Aux_puntos!$1:$1,0))),NA()) | AF36: =IFERROR(IF(INDEX(Aux_puntos!$A$2:$OJ$901,32,MATCH($B$2&"|yC",Aux_puntos!$1:$1,0))="",NA(),INDEX(Aux_puntos!$A$2:$OJ$901,32,MATCH($B$2&"|yC",Aux_puntos!$1:$1,0))),NA()) | AG36: =IFERROR(IF(INDEX(Aux_puntos!$A$2:$OJ$901,32,MATCH($B$2&"|xI",Aux_puntos!$1:$1,0))="",NA(),INDEX(Aux_puntos!$A$2:$OJ$901,32,MATCH($B$2&"|xI",Aux_puntos!$1:$1,0))),NA()) | AH36: =IFERROR(IF(INDEX(Aux_puntos!$A$2:$OJ$901,32,MATCH($B$2&"|yI",Aux_puntos!$1:$1,0))="",NA(),INDEX(Aux_puntos!$A$2:$OJ$901,32,MATCH($B$2&"|yI",Aux_puntos!$1:$1,0))),NA()) | AI36: =IFERROR(IF(INDEX(Aux_puntos!$A$2:$OJ$901,32,MATCH($B$2&"|xN",Aux_puntos!$1:$1,0))="",NA(),INDEX(Aux_puntos!$A$2:$OJ$901,32,MATCH($B$2&"|xN",Aux_puntos!$1:$1,0))),NA()) | AJ36: =IFERROR(IF(INDEX(Aux_puntos!$A$2:$OJ$901,32,MATCH($B$2&"|yN",Aux_puntos!$1:$1,0))="",NA(),INDEX(Aux_puntos!$A$2:$OJ$901,32,MATCH($B$2&"|yN",Aux_puntos!$1:$1,0))),NA())
AC37: =IFERROR(IF(INDEX(Aux_puntos!$A$2:$OJ$901,33,MATCH($B$2&"|xK",Aux_puntos!$1:$1,0))="",NA(),INDEX(Aux_puntos!$A$2:$OJ$901,33,MATCH($B$2&"|xK",Aux_puntos!$1:$1,0))),NA()) | AD37: =IFERROR(IF(INDEX(Aux_puntos!$A$2:$OJ$901,33,MATCH($B$2&"|yK",Aux_puntos!$1:$1,0))="",NA(),INDEX(Aux_puntos!$A$2:$OJ$901,33,MATCH($B$2&"|yK",Aux_puntos!$1:$1,0))),NA()) | AE37: =IFERROR(IF(INDEX(Aux_puntos!$A$2:$OJ$901,33,MATCH($B$2&"|xC",Aux_puntos!$1:$1,0))="",NA(),INDEX(Aux_puntos!$A$2:$OJ$901,33,MATCH($B$2&"|xC",Aux_puntos!$1:$1,0))),NA()) | AF37: =IFERROR(IF(INDEX(Aux_puntos!$A$2:$OJ$901,33,MATCH($B$2&"|yC",Aux_puntos!$1:$1,0))="",NA(),INDEX(Aux_puntos!$A$2:$OJ$901,33,MATCH($B$2&"|yC",Aux_puntos!$1:$1,0))),NA()) | AG37: =IFERROR(IF(INDEX(Aux_puntos!$A$2:$OJ$901,33,MATCH($B$2&"|xI",Aux_puntos!$1:$1,0))="",NA(),INDEX(Aux_puntos!$A$2:$OJ$901,33,MATCH($B$2&"|xI",Aux_puntos!$1:$1,0))),NA()) | AH37: =IFERROR(IF(INDEX(Aux_puntos!$A$2:$OJ$901,33,MATCH($B$2&"|yI",Aux_puntos!$1:$1,0))="",NA(),INDEX(Aux_puntos!$A$2:$OJ$901,33,MATCH($B$2&"|yI",Aux_puntos!$1:$1,0))),NA()) | AI37: =IFERROR(IF(INDEX(Aux_puntos!$A$2:$OJ$901,33,MATCH($B$2&"|xN",Aux_puntos!$1:$1,0))="",NA(),INDEX(Aux_puntos!$A$2:$OJ$901,33,MATCH($B$2&"|xN",Aux_puntos!$1:$1,0))),NA()) | AJ37: =IFERROR(IF(INDEX(Aux_puntos!$A$2:$OJ$901,33,MATCH($B$2&"|yN",Aux_puntos!$1:$1,0))="",NA(),INDEX(Aux_puntos!$A$2:$OJ$901,33,MATCH($B$2&"|yN",Aux_puntos!$1:$1,0))),NA())
AC38: =IFERROR(IF(INDEX(Aux_puntos!$A$2:$OJ$901,34,MATCH($B$2&"|xK",Aux_puntos!$1:$1,0))="",NA(),INDEX(Aux_puntos!$A$2:$OJ$901,34,MATCH($B$2&"|xK",Aux_puntos!$1:$1,0))),NA()) | AD38: =IFERROR(IF(INDEX(Aux_puntos!$A$2:$OJ$901,34,MATCH($B$2&"|yK",Aux_puntos!$1:$1,0))="",NA(),INDEX(Aux_puntos!$A$2:$OJ$901,34,MATCH($B$2&"|yK",Aux_puntos!$1:$1,0))),NA()) | AE38: =IFERROR(IF(INDEX(Aux_puntos!$A$2:$OJ$901,34,MATCH($B$2&"|xC",Aux_puntos!$1:$1,0))="",NA(),INDEX(Aux_puntos!$A$2:$OJ$901,34,MATCH($B$2&"|xC",Aux_puntos!$1:$1,0))),NA()) | AF38: =IFERROR(IF(INDEX(Aux_puntos!$A$2:$OJ$901,34,MATCH($B$2&"|yC",Aux_puntos!$1:$1,0))="",NA(),INDEX(Aux_puntos!$A$2:$OJ$901,34,MATCH($B$2&"|yC",Aux_puntos!$1:$1,0))),NA()) | AG38: =IFERROR(IF(INDEX(Aux_puntos!$A$2:$OJ$901,34,MATCH($B$2&"|xI",Aux_puntos!$1:$1,0))="",NA(),INDEX(Aux_puntos!$A$2:$OJ$901,34,MATCH($B$2&"|xI",Aux_puntos!$1:$1,0))),NA()) | AH38: =IFERROR(IF(INDEX(Aux_puntos!$A$2:$OJ$901,34,MATCH($B$2&"|yI",Aux_puntos!$1:$1,0))="",NA(),INDEX(Aux_puntos!$A$2:$OJ$901,34,MATCH($B$2&"|yI",Aux_puntos!$1:$1,0))),NA()) | AI38: =IFERROR(IF(INDEX(Aux_puntos!$A$2:$OJ$901,34,MATCH($B$2&"|xN",Aux_puntos!$1:$1,0))="",NA(),INDEX(Aux_puntos!$A$2:$OJ$901,34,MATCH($B$2&"|xN",Aux_puntos!$1:$1,0))),NA()) | AJ38: =IFERROR(IF(INDEX(Aux_puntos!$A$2:$OJ$901,34,MATCH($B$2&"|yN",Aux_puntos!$1:$1,0))="",NA(),INDEX(Aux_puntos!$A$2:$OJ$901,34,MATCH($B$2&"|yN",Aux_puntos!$1:$1,0))),NA())
AC39: =IFERROR(IF(INDEX(Aux_puntos!$A$2:$OJ$901,35,MATCH($B$2&"|xK",Aux_puntos!$1:$1,0))="",NA(),INDEX(Aux_puntos!$A$2:$OJ$901,35,MATCH($B$2&"|xK",Aux_puntos!$1:$1,0))),NA()) | AD39: =IFERROR(IF(INDEX(Aux_puntos!$A$2:$OJ$901,35,MATCH($B$2&"|yK",Aux_puntos!$1:$1,0))="",NA(),INDEX(Aux_puntos!$A$2:$OJ$901,35,MATCH($B$2&"|yK",Aux_puntos!$1:$1,0))),NA()) | AE39: =IFERROR(IF(INDEX(Aux_puntos!$A$2:$OJ$901,35,MATCH($B$2&"|xC",Aux_puntos!$1:$1,0))="",NA(),INDEX(Aux_puntos!$A$2:$OJ$901,35,MATCH($B$2&"|xC",Aux_puntos!$1:$1,0))),NA()) | AF39: =IFERROR(IF(INDEX(Aux_puntos!$A$2:$OJ$901,35,MATCH($B$2&"|yC",Aux_puntos!$1:$1,0))="",NA(),INDEX(Aux_puntos!$A$2:$OJ$901,35,MATCH($B$2&"|yC",Aux_puntos!$1:$1,0))),NA()) | AG39: =IFERROR(IF(INDEX(Aux_puntos!$A$2:$OJ$901,35,MATCH($B$2&"|xI",Aux_puntos!$1:$1,0))="",NA(),INDEX(Aux_puntos!$A$2:$OJ$901,35,MATCH($B$2&"|xI",Aux_puntos!$1:$1,0))),NA()) | AH39: =IFERROR(IF(INDEX(Aux_puntos!$A$2:$OJ$901,35,MATCH($B$2&"|yI",Aux_puntos!$1:$1,0))="",NA(),INDEX(Aux_puntos!$A$2:$OJ$901,35,MATCH($B$2&"|yI",Aux_puntos!$1:$1,0))),NA()) | AI39: =IFERROR(IF(INDEX(Aux_puntos!$A$2:$OJ$901,35,MATCH($B$2&"|xN",Aux_puntos!$1:$1,0))="",NA(),INDEX(Aux_puntos!$A$2:$OJ$901,35,MATCH($B$2&"|xN",Aux_puntos!$1:$1,0))),NA()) | AJ39: =IFERROR(IF(INDEX(Aux_puntos!$A$2:$OJ$901,35,MATCH($B$2&"|yN",Aux_puntos!$1:$1,0))="",NA(),INDEX(Aux_puntos!$A$2:$OJ$901,35,MATCH($B$2&"|yN",Aux_puntos!$1:$1,0))),NA())
AC40: =IFERROR(IF(INDEX(Aux_puntos!$A$2:$OJ$901,36,MATCH($B$2&"|xK",Aux_puntos!$1:$1,0))="",NA(),INDEX(Aux_puntos!$A$2:$OJ$901,36,MATCH($B$2&"|xK",Aux_puntos!$1:$1,0))),NA()) | AD40: =IFERROR(IF(INDEX(Aux_puntos!$A$2:$OJ$901,36,MATCH($B$2&"|yK",Aux_puntos!$1:$1,0))="",NA(),INDEX(Aux_puntos!$A$2:$OJ$901,36,MATCH($B$2&"|yK",Aux_puntos!$1:$1,0))),NA()) | AE40: =IFERROR(IF(INDEX(Aux_puntos!$A$2:$OJ$901,36,MATCH($B$2&"|xC",Aux_puntos!$1:$1,0))="",NA(),INDEX(Aux_puntos!$A$2:$OJ$901,36,MATCH($B$2&"|xC",Aux_puntos!$1:$1,0))),NA()) | AF40: =IFERROR(IF(INDEX(Aux_puntos!$A$2:$OJ$901,36,MATCH($B$2&"|yC",Aux_puntos!$1:$1,0))="",NA(),INDEX(Aux_puntos!$A$2:$OJ$901,36,MATCH($B$2&"|yC",Aux_puntos!$1:$1,0))),NA()) | AG40: =IFERROR(IF(INDEX(Aux_puntos!$A$2:$OJ$901,36,MATCH($B$2&"|xI",Aux_puntos!$1:$1,0))="",NA(),INDEX(Aux_puntos!$A$2:$OJ$901,36,MATCH($B$2&"|xI",Aux_puntos!$1:$1,0))),NA()) | AH40: =IFERROR(IF(INDEX(Aux_puntos!$A$2:$OJ$901,36,MATCH($B$2&"|yI",Aux_puntos!$1:$1,0))="",NA(),INDEX(Aux_puntos!$A$2:$OJ$901,36,MATCH($B$2&"|yI",Aux_puntos!$1:$1,0))),NA()) | AI40: =IFERROR(IF(INDEX(Aux_puntos!$A$2:$OJ$901,36,MATCH($B$2&"|xN",Aux_puntos!$1:$1,0))="",NA(),INDEX(Aux_puntos!$A$2:$OJ$901,36,MATCH($B$2&"|xN",Aux_puntos!$1:$1,0))),NA()) | AJ40: =IFERROR(IF(INDEX(Aux_puntos!$A$2:$OJ$901,36,MATCH($B$2&"|yN",Aux_puntos!$1:$1,0))="",NA(),INDEX(Aux_puntos!$A$2:$OJ$901,36,MATCH($B$2&"|yN",Aux_puntos!$1:$1,0))),NA())
